<?xml version="1.0" encoding="utf-8"?>
<!-- =================================================================================== -->
<!-- |    This document was autogenerated by xacro from main.urdf.xacro                | -->
<!-- |    EDITING THIS FILE BY HAND IS NOT RECOMMENDED                                 | -->
<!-- =================================================================================== -->
<robot name="demo_DIR">
  <link name="base_footprint"/>
  <link name="base_link">
    <inertial>
      <origin rpy="0 0 0" xyz="-0.15 0 0.045"/>
      <mass value="5"/>
      <inertia ixx="0.03626" ixy="0" ixz="0" iyy="0.0735" iyz="0" izz="0.10976"/>
    </inertial>
    <visual>
      <origin rpy="-1.57 0 1.57" xyz="0.075 -0.325 0.112"/>
      <geometry>
        <mesh filename="package://demo_navi/src/meshes/base_link.stl"/>
        <scale>0.001 0.001 0.001</scale>
      </geometry>
      <material name="base_material">
        <color rgba="0.098039 0.098039 0.098039 1"/>
      </material>
    </visual>
    <collision>
      <origin rpy="-1.57 0 1.57" xyz="0.075 -0.325 0.112"/>
      <geometry>
        <mesh filename="package://demo_navi/src/meshes/base_link.stl"/>
      </geometry>
    </collision>
  </link>
  <joint name="base_joint" type="fixed">
    <parent link="base_footprint"/>
    <child link="base_link"/>
    <origin xyz="0 0 0.01905"/>
  </joint>
  <link name="rim_left_link">
    <inertial>
      <origin xyz="0 0 0"/>
      <mass value="0.5"/>
      <inertia ixx="2.75e-04" ixy="0" ixz="0" iyy="2.75e-04" iyz="0" izz="3.43e-04"/>
    </inertial>
    <visual>
      <geometry>
        <mesh filename="package://demo_navi/src/meshes/rim.stl"/>
      </geometry>
      <material name="rim_left_material">
        <color rgba="0.3 0 0 1"/>
      </material>
    </visual>
    <collision>
      <geometry>
        <mesh filename="package://demo_navi/src/meshes/rim.stl"/>
      </geometry>
      <surface>
        <friction>
          <ode>
            <mu>0.5</mu>
            <mu2>0.5</mu2>
          </ode>
        </friction>
      </surface>
    </collision>
  </link>
  <joint name="rim_left_joint" type="continuous">
    <parent link="base_link"/>
    <child link="rim_left_link"/>
    <axis xyz="0 0 1"/>
    <origin rpy="1.570796326794896 0 -0.523599" xyz="-0.03 0.215 0.04"/>
    <limit effort="100000" velocity="100000"/>
    <joint_properties friction="1.0"/>
  </joint>
  <link name="roller_s_rim_left_link">
    <inertial>
      <mass value="0.1"/>
      <inertia ixx="2e-05" ixy="0" ixz="0" iyy="2e-05" iyz="0" izz="9e-06"/>
    </inertial>
    <visual>
      <geometry>
        <mesh filename="package://demo_navi/src/meshes/roller.stl"/>
      </geometry>
      <material name="roller_material">
        <color rgba="0.1 0.1 0.1 1"/>
      </material>
    </visual>
    <collision>
      <geometry>
        <mesh filename="package://demo_navi/src/meshes/roller.stl"/>
      </geometry>
      <surface>
        <friction>
          <ode>
            <mu>0.5</mu>
            <mu2>0.5</mu2>
          </ode>
        </friction>
      </surface>
    </collision>
  </link>
  <joint name="roller_s_rim_left_joint" type="continuous">
    <parent link="rim_left_link"/>
    <child link="roller_s_rim_left_link"/>
    <axis xyz="1 0 0"/>
    <origin rpy="0 0 3.1415" xyz="0 -0.025 0.014"/>
    <limit effort="10000000" velocity="1000000"/>
    <joint_properties friction="1.0"/>
  </joint>
  <gazebo reference="roller_s_rim_left_link">
    <dampingFactor>10</dampingFactor>
    <minDepth>0.001</minDepth>
  </gazebo>
  <gazebo reference="roller_s_rim_left_joint">
    <dampingFactor>10</dampingFactor>
    <minDepth>0.001</minDepth>
  </gazebo>
  <link name="roller_nw_rim_left_link">
    <inertial>
      <mass value="0.1"/>
      <inertia ixx="2e-05" ixy="0" ixz="0" iyy="2e-05" iyz="0" izz="9e-06"/>
    </inertial>
    <visual>
      <geometry>
        <mesh filename="package://demo_navi/src/meshes/roller.stl"/>
      </geometry>
      <material name="roller_material">
        <color rgba="0.1 0.1 0.1 1"/>
      </material>
    </visual>
    <collision>
      <geometry>
        <mesh filename="package://demo_navi/src/meshes/roller.stl"/>
      </geometry>
      <surface>
        <friction>
          <ode>
            <mu>0.5</mu>
            <mu2>0.5</mu2>
          </ode>
        </friction>
      </surface>
    </collision>
  </link>
  <joint name="roller_nw_rim_left_joint" type="continuous">
    <parent link="rim_left_link"/>
    <child link="roller_nw_rim_left_link"/>
    <axis xyz="1 0 0"/>
    <origin rpy="0 0 1.0472" xyz="-0.0215 0.0125 0.014"/>
    <limit effort="10000000" velocity="1000000"/>
    <joint_properties friction="1.0"/>
  </joint>
  <gazebo reference="roller_nw_rim_left_link">
    <dampingFactor>10</dampingFactor>
    <minDepth>0.001</minDepth>
  </gazebo>
  <gazebo reference="roller_nw_rim_left_joint">
    <dampingFactor>10</dampingFactor>
    <minDepth>0.001</minDepth>
  </gazebo>
  <link name="roller_ne_rim_left_link">
    <inertial>
      <mass value="0.1"/>
      <inertia ixx="2e-05" ixy="0" ixz="0" iyy="2e-05" iyz="0" izz="9e-06"/>
    </inertial>
    <visual>
      <geometry>
        <mesh filename="package://demo_navi/src/meshes/roller.stl"/>
      </geometry>
      <material name="roller_material">
        <color rgba="0.1 0.1 0.1 1"/>
      </material>
    </visual>
    <collision>
      <geometry>
        <mesh filename="package://demo_navi/src/meshes/roller.stl"/>
      </geometry>
      <surface>
        <friction>
          <ode>
            <mu>0.5</mu>
            <mu2>0.5</mu2>
          </ode>
        </friction>
      </surface>
    </collision>
  </link>
  <joint name="roller_ne_rim_left_joint" type="continuous">
    <parent link="rim_left_link"/>
    <child link="roller_ne_rim_left_link"/>
    <axis xyz="1 0 0"/>
    <origin rpy="0 0 -1.0472" xyz="0.0215 0.0125 0.014"/>
    <limit effort="10000000" velocity="1000000"/>
    <joint_properties friction="1.0"/>
  </joint>
  <gazebo reference="roller_ne_rim_left_link">
    <dampingFactor>10</dampingFactor>
    <minDepth>0.001</minDepth>
  </gazebo>
  <gazebo reference="roller_ne_rim_left_joint">
    <dampingFactor>10</dampingFactor>
    <minDepth>0.001</minDepth>
  </gazebo>
  <link name="roller_sw_rim_left_link">
    <inertial>
      <mass value="0.1"/>
      <inertia ixx="2e-05" ixy="0" ixz="0" iyy="2e-05" iyz="0" izz="9e-06"/>
    </inertial>
    <visual>
      <geometry>
        <mesh filename="package://demo_navi/src/meshes/roller.stl"/>
      </geometry>
      <material name="roller_material">
        <color rgba="0.1 0.1 0.1 1"/>
      </material>
    </visual>
    <collision>
      <geometry>
        <mesh filename="package://demo_navi/src/meshes/roller.stl"/>
      </geometry>
      <surface>
        <friction>
          <ode>
            <mu>0.5</mu>
            <mu2>0.5</mu2>
          </ode>
        </friction>
      </surface>
    </collision>
  </link>
  <joint name="roller_sw_rim_left_joint" type="continuous">
    <parent link="rim_left_link"/>
    <child link="roller_sw_rim_left_link"/>
    <axis xyz="1 0 0"/>
    <origin rpy="0 0 1.0472" xyz="0.0215 -0.0125 -0.014"/>
    <limit effort="10000000" velocity="1000000"/>
    <joint_properties friction="1.0"/>
  </joint>
  <gazebo reference="roller_sw_rim_left_link">
    <dampingFactor>10</dampingFactor>
    <minDepth>0.001</minDepth>
  </gazebo>
  <gazebo reference="roller_sw_rim_left_joint">
    <dampingFactor>10</dampingFactor>
    <minDepth>0.001</minDepth>
  </gazebo>
  <link name="roller_n_rim_left_link">
    <inertial>
      <mass value="0.1"/>
      <inertia ixx="2e-05" ixy="0" ixz="0" iyy="2e-05" iyz="0" izz="9e-06"/>
    </inertial>
    <visual>
      <geometry>
        <mesh filename="package://demo_navi/src/meshes/roller.stl"/>
      </geometry>
      <material name="roller_material">
        <color rgba="0.1 0.1 0.1 1"/>
      </material>
    </visual>
    <collision>
      <geometry>
        <mesh filename="package://demo_navi/src/meshes/roller.stl"/>
      </geometry>
      <surface>
        <friction>
          <ode>
            <mu>0.5</mu>
            <mu2>0.5</mu2>
          </ode>
        </friction>
      </surface>
    </collision>
  </link>
  <joint name="roller_n_rim_left_joint" type="continuous">
    <parent link="rim_left_link"/>
    <child link="roller_n_rim_left_link"/>
    <axis xyz="1 0 0"/>
    <origin rpy="0 0 3.1415" xyz="0 0.025 -0.014"/>
    <limit effort="10000000" velocity="1000000"/>
    <joint_properties friction="1.0"/>
  </joint>
  <gazebo reference="roller_n_rim_left_link">
    <dampingFactor>10</dampingFactor>
    <minDepth>0.001</minDepth>
  </gazebo>
  <gazebo reference="roller_n_rim_left_joint">
    <dampingFactor>10</dampingFactor>
    <minDepth>0.001</minDepth>
  </gazebo>
  <link name="roller_se_rim_left_link">
    <inertial>
      <mass value="0.1"/>
      <inertia ixx="2e-05" ixy="0" ixz="0" iyy="2e-05" iyz="0" izz="9e-06"/>
    </inertial>
    <visual>
      <geometry>
        <mesh filename="package://demo_navi/src/meshes/roller.stl"/>
      </geometry>
      <material name="roller_material">
        <color rgba="0.1 0.1 0.1 1"/>
      </material>
    </visual>
    <collision>
      <geometry>
        <mesh filename="package://demo_navi/src/meshes/roller.stl"/>
      </geometry>
      <surface>
        <friction>
          <ode>
            <mu>0.5</mu>
            <mu2>0.5</mu2>
          </ode>
        </friction>
      </surface>
    </collision>
  </link>
  <joint name="roller_se_rim_left_joint" type="continuous">
    <parent link="rim_left_link"/>
    <child link="roller_se_rim_left_link"/>
    <axis xyz="1 0 0"/>
    <origin rpy="0 0 -1.0472" xyz="-0.0215 -0.0125 -0.014"/>
    <limit effort="10000000" velocity="1000000"/>
    <joint_properties friction="1.0"/>
  </joint>
  <gazebo reference="roller_se_rim_left_link">
    <dampingFactor>10</dampingFactor>
    <minDepth>0.001</minDepth>
  </gazebo>
  <gazebo reference="roller_se_rim_left_joint">
    <dampingFactor>10</dampingFactor>
    <minDepth>0.001</minDepth>
  </gazebo>
  <transmission name="rim_left_transmission">
    <type>transmission_interface/SimpleTransmission</type>
    <joint name="rim_left_joint">
      <hardwareInterface>hardware_interface/EffortJointInterface</hardwareInterface>
    </joint>
    <actuator name="rim_left_motor">
      <hardwareInterface>hardware_interface/EffortJointInterface</hardwareInterface>
      <mechanicalReduction>1</mechanicalReduction>
    </actuator>
  </transmission>
  <gazebo reference="rim_left_link">
    <dampingFactor>10</dampingFactor>
    <minDepth>0.001</minDepth>
  </gazebo>
  <gazebo reference="rim_left_joint">
    <dampingFactor>10</dampingFactor>
    <minDepth>0.001</minDepth>
  </gazebo>
  <link name="rim_back_link">
    <inertial>
      <origin xyz="0 0 0"/>
      <mass value="0.5"/>
      <inertia ixx="2.75e-04" ixy="0" ixz="0" iyy="2.75e-04" iyz="0" izz="3.43e-04"/>
    </inertial>
    <visual>
      <geometry>
        <mesh filename="package://demo_navi/src/meshes/rim.stl"/>
      </geometry>
      <material name="rim_back_material">
        <color rgba="0.3 0 0 1"/>
      </material>
    </visual>
    <collision>
      <geometry>
        <mesh filename="package://demo_navi/src/meshes/rim.stl"/>
      </geometry>
      <surface>
        <friction>
          <ode>
            <mu>0.5</mu>
            <mu2>0.5</mu2>
          </ode>
        </friction>
      </surface>
    </collision>
  </link>
  <joint name="rim_back_joint" type="continuous">
    <parent link="base_link"/>
    <child link="rim_back_link"/>
    <axis xyz="0 0 1"/>
    <origin rpy="1.570796326794896 0 1.5708" xyz="-0.397 0 0.04"/>
    <limit effort="100000" velocity="100000"/>
    <joint_properties friction="1.0"/>
  </joint>
  <link name="roller_s_rim_back_link">
    <inertial>
      <mass value="0.1"/>
      <inertia ixx="2e-05" ixy="0" ixz="0" iyy="2e-05" iyz="0" izz="9e-06"/>
    </inertial>
    <visual>
      <geometry>
        <mesh filename="package://demo_navi/src/meshes/roller.stl"/>
      </geometry>
      <material name="roller_material">
        <color rgba="0.1 0.1 0.1 1"/>
      </material>
    </visual>
    <collision>
      <geometry>
        <mesh filename="package://demo_navi/src/meshes/roller.stl"/>
      </geometry>
      <surface>
        <friction>
          <ode>
            <mu>0.5</mu>
            <mu2>0.5</mu2>
          </ode>
        </friction>
      </surface>
    </collision>
  </link>
  <joint name="roller_s_rim_back_joint" type="continuous">
    <parent link="rim_back_link"/>
    <child link="roller_s_rim_back_link"/>
    <axis xyz="1 0 0"/>
    <origin rpy="0 0 3.1415" xyz="0 -0.025 0.014"/>
    <limit effort="10000000" velocity="1000000"/>
    <joint_properties friction="1.0"/>
  </joint>
  <gazebo reference="roller_s_rim_back_link">
    <dampingFactor>10</dampingFactor>
    <minDepth>0.001</minDepth>
  </gazebo>
  <gazebo reference="roller_s_rim_back_joint">
    <dampingFactor>10</dampingFactor>
    <minDepth>0.001</minDepth>
  </gazebo>
  <link name="roller_nw_rim_back_link">
    <inertial>
      <mass value="0.1"/>
      <inertia ixx="2e-05" ixy="0" ixz="0" iyy="2e-05" iyz="0" izz="9e-06"/>
    </inertial>
    <visual>
      <geometry>
        <mesh filename="package://demo_navi/src/meshes/roller.stl"/>
      </geometry>
      <material name="roller_material">
        <color rgba="0.1 0.1 0.1 1"/>
      </material>
    </visual>
    <collision>
      <geometry>
        <mesh filename="package://demo_navi/src/meshes/roller.stl"/>
      </geometry>
      <surface>
        <friction>
          <ode>
            <mu>0.5</mu>
            <mu2>0.5</mu2>
          </ode>
        </friction>
      </surface>
    </collision>
  </link>
  <joint name="roller_nw_rim_back_joint" type="continuous">
    <parent link="rim_back_link"/>
    <child link="roller_nw_rim_back_link"/>
    <axis xyz="1 0 0"/>
    <origin rpy="0 0 1.0472" xyz="-0.0215 0.0125 0.014"/>
    <limit effort="10000000" velocity="1000000"/>
    <joint_properties friction="1.0"/>
  </joint>
  <gazebo reference="roller_nw_rim_back_link">
    <dampingFactor>10</dampingFactor>
    <minDepth>0.001</minDepth>
  </gazebo>
  <gazebo reference="roller_nw_rim_back_joint">
    <dampingFactor>10</dampingFactor>
    <minDepth>0.001</minDepth>
  </gazebo>
  <link name="roller_ne_rim_back_link">
    <inertial>
      <mass value="0.1"/>
      <inertia ixx="2e-05" ixy="0" ixz="0" iyy="2e-05" iyz="0" izz="9e-06"/>
    </inertial>
    <visual>
      <geometry>
        <mesh filename="package://demo_navi/src/meshes/roller.stl"/>
      </geometry>
      <material name="roller_material">
        <color rgba="0.1 0.1 0.1 1"/>
      </material>
    </visual>
    <collision>
      <geometry>
        <mesh filename="package://demo_navi/src/meshes/roller.stl"/>
      </geometry>
      <surface>
        <friction>
          <ode>
            <mu>0.5</mu>
            <mu2>0.5</mu2>
          </ode>
        </friction>
      </surface>
    </collision>
  </link>
  <joint name="roller_ne_rim_back_joint" type="continuous">
    <parent link="rim_back_link"/>
    <child link="roller_ne_rim_back_link"/>
    <axis xyz="1 0 0"/>
    <origin rpy="0 0 -1.0472" xyz="0.0215 0.0125 0.014"/>
    <limit effort="10000000" velocity="1000000"/>
    <joint_properties friction="1.0"/>
  </joint>
  <gazebo reference="roller_ne_rim_back_link">
    <dampingFactor>10</dampingFactor>
    <minDepth>0.001</minDepth>
  </gazebo>
  <gazebo reference="roller_ne_rim_back_joint">
    <dampingFactor>10</dampingFactor>
    <minDepth>0.001</minDepth>
  </gazebo>
  <link name="roller_sw_rim_back_link">
    <inertial>
      <mass value="0.1"/>
      <inertia ixx="2e-05" ixy="0" ixz="0" iyy="2e-05" iyz="0" izz="9e-06"/>
    </inertial>
    <visual>
      <geometry>
        <mesh filename="package://demo_navi/src/meshes/roller.stl"/>
      </geometry>
      <material name="roller_material">
        <color rgba="0.1 0.1 0.1 1"/>
      </material>
    </visual>
    <collision>
      <geometry>
        <mesh filename="package://demo_navi/src/meshes/roller.stl"/>
      </geometry>
      <surface>
        <friction>
          <ode>
            <mu>0.5</mu>
            <mu2>0.5</mu2>
          </ode>
        </friction>
      </surface>
    </collision>
  </link>
  <joint name="roller_sw_rim_back_joint" type="continuous">
    <parent link="rim_back_link"/>
    <child link="roller_sw_rim_back_link"/>
    <axis xyz="1 0 0"/>
    <origin rpy="0 0 1.0472" xyz="0.0215 -0.0125 -0.014"/>
    <limit effort="10000000" velocity="1000000"/>
    <joint_properties friction="1.0"/>
  </joint>
  <gazebo reference="roller_sw_rim_back_link">
    <dampingFactor>10</dampingFactor>
    <minDepth>0.001</minDepth>
  </gazebo>
  <gazebo reference="roller_sw_rim_back_joint">
    <dampingFactor>10</dampingFactor>
    <minDepth>0.001</minDepth>
  </gazebo>
  <link name="roller_n_rim_back_link">
    <inertial>
      <mass value="0.1"/>
      <inertia ixx="2e-05" ixy="0" ixz="0" iyy="2e-05" iyz="0" izz="9e-06"/>
    </inertial>
    <visual>
      <geometry>
        <mesh filename="package://demo_navi/src/meshes/roller.stl"/>
      </geometry>
      <material name="roller_material">
        <color rgba="0.1 0.1 0.1 1"/>
      </material>
    </visual>
    <collision>
      <geometry>
        <mesh filename="package://demo_navi/src/meshes/roller.stl"/>
      </geometry>
      <surface>
        <friction>
          <ode>
            <mu>0.5</mu>
            <mu2>0.5</mu2>
          </ode>
        </friction>
      </surface>
    </collision>
  </link>
  <joint name="roller_n_rim_back_joint" type="continuous">
    <parent link="rim_back_link"/>
    <child link="roller_n_rim_back_link"/>
    <axis xyz="1 0 0"/>
    <origin rpy="0 0 3.1415" xyz="0 0.025 -0.014"/>
    <limit effort="10000000" velocity="1000000"/>
    <joint_properties friction="1.0"/>
  </joint>
  <gazebo reference="roller_n_rim_back_link">
    <dampingFactor>10</dampingFactor>
    <minDepth>0.001</minDepth>
  </gazebo>
  <gazebo reference="roller_n_rim_back_joint">
    <dampingFactor>10</dampingFactor>
    <minDepth>0.001</minDepth>
  </gazebo>
  <link name="roller_se_rim_back_link">
    <inertial>
      <mass value="0.1"/>
      <inertia ixx="2e-05" ixy="0" ixz="0" iyy="2e-05" iyz="0" izz="9e-06"/>
    </inertial>
    <visual>
      <geometry>
        <mesh filename="package://demo_navi/src/meshes/roller.stl"/>
      </geometry>
      <material name="roller_material">
        <color rgba="0.1 0.1 0.1 1"/>
      </material>
    </visual>
    <collision>
      <geometry>
        <mesh filename="package://demo_navi/src/meshes/roller.stl"/>
      </geometry>
      <surface>
        <friction>
          <ode>
            <mu>0.5</mu>
            <mu2>0.5</mu2>
          </ode>
        </friction>
      </surface>
    </collision>
  </link>
  <joint name="roller_se_rim_back_joint" type="continuous">
    <parent link="rim_back_link"/>
    <child link="roller_se_rim_back_link"/>
    <axis xyz="1 0 0"/>
    <origin rpy="0 0 -1.0472" xyz="-0.0215 -0.0125 -0.014"/>
    <limit effort="10000000" velocity="1000000"/>
    <joint_properties friction="1.0"/>
  </joint>
  <gazebo reference="roller_se_rim_back_link">
    <dampingFactor>10</dampingFactor>
    <minDepth>0.001</minDepth>
  </gazebo>
  <gazebo reference="roller_se_rim_back_joint">
    <dampingFactor>10</dampingFactor>
    <minDepth>0.001</minDepth>
  </gazebo>
  <transmission name="rim_back_transmission">
    <type>transmission_interface/SimpleTransmission</type>
    <joint name="rim_back_joint">
      <hardwareInterface>hardware_interface/EffortJointInterface</hardwareInterface>
    </joint>
    <actuator name="rim_back_motor">
      <hardwareInterface>hardware_interface/EffortJointInterface</hardwareInterface>
      <mechanicalReduction>1</mechanicalReduction>
    </actuator>
  </transmission>
  <gazebo reference="rim_back_link">
    <dampingFactor>10</dampingFactor>
    <minDepth>0.001</minDepth>
  </gazebo>
  <gazebo reference="rim_back_joint">
    <dampingFactor>10</dampingFactor>
    <minDepth>0.001</minDepth>
  </gazebo>
  <link name="rim_right_link">
    <inertial>
      <origin xyz="0 0 0"/>
      <mass value="0.5"/>
      <inertia ixx="2.75e-04" ixy="0" ixz="0" iyy="2.75e-04" iyz="0" izz="3.43e-04"/>
    </inertial>
    <visual>
      <geometry>
        <mesh filename="package://demo_navi/src/meshes/rim.stl"/>
      </geometry>
      <material name="rim_right_material">
        <color rgba="0.3 0 0 1"/>
      </material>
    </visual>
    <collision>
      <geometry>
        <mesh filename="package://demo_navi/src/meshes/rim.stl"/>
      </geometry>
      <surface>
        <friction>
          <ode>
            <mu>0.5</mu>
            <mu2>0.5</mu2>
          </ode>
        </friction>
      </surface>
    </collision>
  </link>
  <joint name="rim_right_joint" type="continuous">
    <parent link="base_link"/>
    <child link="rim_right_link"/>
    <axis xyz="0 0 1"/>
    <origin rpy="1.570796326794896 0 -2.61799" xyz="-0.03 -0.208 0.04"/>
    <limit effort="100000" velocity="100000"/>
    <joint_properties friction="1.0"/>
  </joint>
  <link name="roller_s_rim_right_link">
    <inertial>
      <mass value="0.1"/>
      <inertia ixx="2e-05" ixy="0" ixz="0" iyy="2e-05" iyz="0" izz="9e-06"/>
    </inertial>
    <visual>
      <geometry>
        <mesh filename="package://demo_navi/src/meshes/roller.stl"/>
      </geometry>
      <material name="roller_material">
        <color rgba="0.1 0.1 0.1 1"/>
      </material>
    </visual>
    <collision>
      <geometry>
        <mesh filename="package://demo_navi/src/meshes/roller.stl"/>
      </geometry>
      <surface>
        <friction>
          <ode>
            <mu>0.5</mu>
            <mu2>0.5</mu2>
          </ode>
        </friction>
      </surface>
    </collision>
  </link>
  <joint name="roller_s_rim_right_joint" type="continuous">
    <parent link="rim_right_link"/>
    <child link="roller_s_rim_right_link"/>
    <axis xyz="1 0 0"/>
    <origin rpy="0 0 3.1415" xyz="0 -0.025 0.014"/>
    <limit effort="10000000" velocity="1000000"/>
    <joint_properties friction="1.0"/>
  </joint>
  <gazebo reference="roller_s_rim_right_link">
    <dampingFactor>10</dampingFactor>
    <minDepth>0.001</minDepth>
  </gazebo>
  <gazebo reference="roller_s_rim_right_joint">
    <dampingFactor>10</dampingFactor>
    <minDepth>0.001</minDepth>
  </gazebo>
  <link name="roller_nw_rim_right_link">
    <inertial>
      <mass value="0.1"/>
      <inertia ixx="2e-05" ixy="0" ixz="0" iyy="2e-05" iyz="0" izz="9e-06"/>
    </inertial>
    <visual>
      <geometry>
        <mesh filename="package://demo_navi/src/meshes/roller.stl"/>
      </geometry>
      <material name="roller_material">
        <color rgba="0.1 0.1 0.1 1"/>
      </material>
    </visual>
    <collision>
      <geometry>
        <mesh filename="package://demo_navi/src/meshes/roller.stl"/>
      </geometry>
      <surface>
        <friction>
          <ode>
            <mu>0.5</mu>
            <mu2>0.5</mu2>
          </ode>
        </friction>
      </surface>
    </collision>
  </link>
  <joint name="roller_nw_rim_right_joint" type="continuous">
    <parent link="rim_right_link"/>
    <child link="roller_nw_rim_right_link"/>
    <axis xyz="1 0 0"/>
    <origin rpy="0 0 1.0472" xyz="-0.0215 0.0125 0.014"/>
    <limit effort="10000000" velocity="1000000"/>
    <joint_properties friction="1.0"/>
  </joint>
  <gazebo reference="roller_nw_rim_right_link">
    <dampingFactor>10</dampingFactor>
    <minDepth>0.001</minDepth>
  </gazebo>
  <gazebo reference="roller_nw_rim_right_joint">
    <dampingFactor>10</dampingFactor>
    <minDepth>0.001</minDepth>
  </gazebo>
  <link name="roller_ne_rim_right_link">
    <inertial>
      <mass value="0.1"/>
      <inertia ixx="2e-05" ixy="0" ixz="0" iyy="2e-05" iyz="0" izz="9e-06"/>
    </inertial>
    <visual>
      <geometry>
        <mesh filename="package://demo_navi/src/meshes/roller.stl"/>
      </geometry>
      <material name="roller_material">
        <color rgba="0.1 0.1 0.1 1"/>
      </material>
    </visual>
    <collision>
      <geometry>
        <mesh filename="package://demo_navi/src/meshes/roller.stl"/>
      </geometry>
      <surface>
        <friction>
          <ode>
            <mu>0.5</mu>
            <mu2>0.5</mu2>
          </ode>
        </friction>
      </surface>
    </collision>
  </link>
  <joint name="roller_ne_rim_right_joint" type="continuous">
    <parent link="rim_right_link"/>
    <child link="roller_ne_rim_right_link"/>
    <axis xyz="1 0 0"/>
    <origin rpy="0 0 -1.0472" xyz="0.0215 0.0125 0.014"/>
    <limit effort="10000000" velocity="1000000"/>
    <joint_properties friction="1.0"/>
  </joint>
  <gazebo reference="roller_ne_rim_right_link">
    <dampingFactor>10</dampingFactor>
    <minDepth>0.001</minDepth>
  </gazebo>
  <gazebo reference="roller_ne_rim_right_joint">
    <dampingFactor>10</dampingFactor>
    <minDepth>0.001</minDepth>
  </gazebo>
  <link name="roller_sw_rim_right_link">
    <inertial>
      <mass value="0.1"/>
      <inertia ixx="2e-05" ixy="0" ixz="0" iyy="2e-05" iyz="0" izz="9e-06"/>
    </inertial>
    <visual>
      <geometry>
        <mesh filename="package://demo_navi/src/meshes/roller.stl"/>
      </geometry>
      <material name="roller_material">
        <color rgba="0.1 0.1 0.1 1"/>
      </material>
    </visual>
    <collision>
      <geometry>
        <mesh filename="package://demo_navi/src/meshes/roller.stl"/>
      </geometry>
      <surface>
        <friction>
          <ode>
            <mu>0.5</mu>
            <mu2>0.5</mu2>
          </ode>
        </friction>
      </surface>
    </collision>
  </link>
  <joint name="roller_sw_rim_right_joint" type="continuous">
    <parent link="rim_right_link"/>
    <child link="roller_sw_rim_right_link"/>
    <axis xyz="1 0 0"/>
    <origin rpy="0 0 1.0472" xyz="0.0215 -0.0125 -0.014"/>
    <limit effort="10000000" velocity="1000000"/>
    <joint_properties friction="1.0"/>
  </joint>
  <gazebo reference="roller_sw_rim_right_link">
    <dampingFactor>10</dampingFactor>
    <minDepth>0.001</minDepth>
  </gazebo>
  <gazebo reference="roller_sw_rim_right_joint">
    <dampingFactor>10</dampingFactor>
    <minDepth>0.001</minDepth>
  </gazebo>
  <link name="roller_n_rim_right_link">
    <inertial>
      <mass value="0.1"/>
      <inertia ixx="2e-05" ixy="0" ixz="0" iyy="2e-05" iyz="0" izz="9e-06"/>
    </inertial>
    <visual>
      <geometry>
        <mesh filename="package://demo_navi/src/meshes/roller.stl"/>
      </geometry>
      <material name="roller_material">
        <color rgba="0.1 0.1 0.1 1"/>
      </material>
    </visual>
    <collision>
      <geometry>
        <mesh filename="package://demo_navi/src/meshes/roller.stl"/>
      </geometry>
      <surface>
        <friction>
          <ode>
            <mu>0.5</mu>
            <mu2>0.5</mu2>
          </ode>
        </friction>
      </surface>
    </collision>
  </link>
  <joint name="roller_n_rim_right_joint" type="continuous">
    <parent link="rim_right_link"/>
    <child link="roller_n_rim_right_link"/>
    <axis xyz="1 0 0"/>
    <origin rpy="0 0 3.1415" xyz="0 0.025 -0.014"/>
    <limit effort="10000000" velocity="1000000"/>
    <joint_properties friction="1.0"/>
  </joint>
  <gazebo reference="roller_n_rim_right_link">
    <dampingFactor>10</dampingFactor>
    <minDepth>0.001</minDepth>
  </gazebo>
  <gazebo reference="roller_n_rim_right_joint">
    <dampingFactor>10</dampingFactor>
    <minDepth>0.001</minDepth>
  </gazebo>
  <link name="roller_se_rim_right_link">
    <inertial>
      <mass value="0.1"/>
      <inertia ixx="2e-05" ixy="0" ixz="0" iyy="2e-05" iyz="0" izz="9e-06"/>
    </inertial>
    <visual>
      <geometry>
        <mesh filename="package://demo_navi/src/meshes/roller.stl"/>
      </geometry>
      <material name="roller_material">
        <color rgba="0.1 0.1 0.1 1"/>
      </material>
    </visual>
    <collision>
      <geometry>
        <mesh filename="package://demo_navi/src/meshes/roller.stl"/>
      </geometry>
      <surface>
        <friction>
          <ode>
            <mu>0.5</mu>
            <mu2>0.5</mu2>
          </ode>
        </friction>
      </surface>
    </collision>
  </link>
  <joint name="roller_se_rim_right_joint" type="continuous">
    <parent link="rim_right_link"/>
    <child link="roller_se_rim_right_link"/>
    <axis xyz="1 0 0"/>
    <origin rpy="0 0 -1.0472" xyz="-0.0215 -0.0125 -0.014"/>
    <limit effort="10000000" velocity="1000000"/>
    <joint_properties friction="1.0"/>
  </joint>
  <gazebo reference="roller_se_rim_right_link">
    <dampingFactor>10</dampingFactor>
    <minDepth>0.001</minDepth>
  </gazebo>
  <gazebo reference="roller_se_rim_right_joint">
    <dampingFactor>10</dampingFactor>
    <minDepth>0.001</minDepth>
  </gazebo>
  <transmission name="rim_right_transmission">
    <type>transmission_interface/SimpleTransmission</type>
    <joint name="rim_right_joint">
      <hardwareInterface>hardware_interface/EffortJointInterface</hardwareInterface>
    </joint>
    <actuator name="rim_right_motor">
      <hardwareInterface>hardware_interface/EffortJointInterface</hardwareInterface>
      <mechanicalReduction>1</mechanicalReduction>
    </actuator>
  </transmission>
  <gazebo reference="rim_right_link">
    <dampingFactor>10</dampingFactor>
    <minDepth>0.001</minDepth>
  </gazebo>
  <gazebo reference="rim_right_joint">
    <dampingFactor>10</dampingFactor>
    <minDepth>0.001</minDepth>
  </gazebo>
  <joint name="sick_joint_R" type="fixed">
    <parent link="base_link"/>
    <child link="sick_R_laser"/>
    <!-- allakse to adress -->
    <origin rpy="0 0 -1.0471" xyz="0 -0.27 0.086"/>
  </joint>
  <link name="sick_R_laser">
    <visual>
      <geometry>
        <mesh filename="package://demo_navi/src/meshes/LMS5xx_small.dae" scale="0.0003 0.0003 0.0003"/>
      </geometry>
      <material name="blue">
        <color rgba="0 0 1 1"/>
      </material>
    </visual>
    <!--<collision>
        <geometry>
          <mesh filename="package://sick_scan/meshes/LMS5xx_collision.stl" scale="0.3 0.3 0.3"/>
        </geometry>
      </collision>-->
    <inertial>
      <mass value="0.001"/>
      <origin xyz="0 -0.27 0.086"/>
      <inertia ixx="0.000001" ixy="0.0" ixz="0.0" iyy="0.000001" iyz="0.0" izz="0.000001"/>
    </inertial>
  </link>
  <joint name="sick_joint_L" type="fixed">
    <parent link="base_link"/>
    <child link="sick_L_laser"/>
    <origin rpy="0 0 1.0471" xyz="0 0.27 0.086"/>
  </joint>
  <link name="sick_L_laser">
    <visual>
      <geometry>
        <mesh filename="package://demo_navi/src/meshes/LMS5xx_small.dae" scale="0.0003 0.0003 0.0003"/>
      </geometry>
      <material name="blue">
        <color rgba="0 0 1 1"/>
      </material>
    </visual>
    <!--<collision>
        <geometry>
          <mesh filename="package://sick_scan/meshes/LMS5xx_collision.stl" scale="0.3 0.3 0.3" />
        </geometry>
      </collision>-->
    <inertial>
      <mass value="0.001"/>
      <origin xyz="0 0.27 0.086"/>
      <inertia ixx="0.000001" ixy="0.0" ixz="0.0" iyy="0.000001" iyz="0.0" izz="0.000001"/>
    </inertial>
  </link>
  <gazebo>
    <plugin filename="libgazebo_ros_control.so" name="gazebo_ros_control">
      <robotNamespace>/demo_DIR</robotNamespace>
    </plugin>
  </gazebo>
  <gazebo reference="base_link">
    <dampingFactor>10</dampingFactor>
    <minDepth>0.001</minDepth>
  </gazebo>
  <gazebo>
    <plugin filename="libgazebo_ros_planar_move.so" name="object_controller">
      <commandTopic>cmd_vel</commandTopic>
      <leftJoint>left_rim_joint</leftJoint>
      <rightJoint>right_rim_joint</rightJoint>
      <backJoint>back_rim_joint</backJoint>
      <wheelSeparation>0.25</wheelSeparation>
      <wheelDiameter>0.7</wheelDiameter>
      <torque>10</torque>
      <odometryTopic>odom</odometryTopic>
      <odometryFrame>odom</odometryFrame>
      <odometryRate>20.0</odometryRate>
      <robotBaseFrame>base_footprint</robotBaseFrame>
    </plugin>
  </gazebo>
  <gazebo reference="sick_L_laser">
    <material value="Gazebo/Blue"/>
    <sensor name="sick_lms_5_laser_gazebo_v0" type="ray">
      <always_on>true</always_on>
      <update_rate>15.0</update_rate>
      <pose>0 0 0 0 0 0</pose>
      <visualize>false</visualize>
      <ray>
        <scan>
          <horizontal>
            <samples>811</samples>
            <resolution>1</resolution>
            <min_angle>-1.5708</min_angle>
            <!--90 moires -->
            <max_angle>2.357</max_angle>
            <!--140 moires -->
          </horizontal>
        </scan>
        <range>
          <min>0.05</min>
          <max>4.0</max>
          <resolution>0.01</resolution>
        </range>
      </ray>
      <plugin filename="libgazebo_ros_laser.so" name="gazebo_ros_sick_lms_5_laser_gazebo_v0_controller">
        <gaussianNoise>0.005</gaussianNoise>
        <alwaysOn>true</alwaysOn>
        <updateRate>15.0</updateRate>
        <topicName>scan_L</topicName>
        <frameName>sick_L_laser</frameName>
      </plugin>
    </sensor>
  </gazebo>
  <gazebo reference="sick_R_laser">
    <material value="Gazebo/Blue"/>
    <sensor name="sick_lms_5_laser_gazebo_v01" type="ray">
      <always_on>true</always_on>
      <update_rate>15.0</update_rate>
      <pose>0 0 0 0 0 0</pose>
      <visualize>false</visualize>
      <ray>
        <scan>
          <horizontal>
            <samples>811</samples>
            <resolution>1</resolution>
            <min_angle>-2.357</min_angle>
            <!--140 moires -->
            <max_angle>1.5708</max_angle>
            <!--90 moires -->
          </horizontal>
        </scan>
        <range>
          <min>0.05</min>
          <max>4.0</max>
          <resolution>0.01</resolution>
        </range>
      </ray>
      <plugin filename="libgazebo_ros_laser.so" name="gazebo_ros_sick_lms_5_laser_gazebo_v01_controller">
        <gaussianNoise>0.005</gaussianNoise>
        <alwaysOn>true</alwaysOn>
        <updateRate>15.0</updateRate>
        <topicName>scan_R</topicName>
        <!-- allakse ta topics nomizw pws prepei na mpoun ws scan kai ta duo(scan_L & scan_R) -->
        <frameName>sick_R_laser</frameName>
      </plugin>
    </sensor>
  </gazebo>
</robot>
