<?xml version="1.0" encoding="utf-8"?>
<!-- =================================================================================== -->
<!-- |    This document was autogenerated by xacro from main.urdf.xacro                | -->
<!-- |    EDITING THIS FILE BY HAND IS NOT RECOMMENDED                                 | -->
<!-- =================================================================================== -->
<robot name="demo_DIR">
  <transmission name="tran1">
    <type>transmission_interface/SimpleTransmission</type>
    <joint name="joint_1">
      <hardwareInterface>hardware_interface/EffortJointInterface</hardwareInterface>
    </joint>
    <actuator name="motor1">
      <hardwareInterface>hardware_interface/EffortJointInterface</hardwareInterface>
      <mechanicalReduction>1</mechanicalReduction>
    </actuator>
  </transmission>
  <transmission name="tran2">
    <type>transmission_interface/SimpleTransmission</type>
    <joint name="joint_2">
      <hardwareInterface>hardware_interface/EffortJointInterface</hardwareInterface>
    </joint>
    <actuator name="motor2">
      <hardwareInterface>hardware_interface/EffortJointInterface</hardwareInterface>
      <mechanicalReduction>1</mechanicalReduction>
    </actuator>
  </transmission>
  <transmission name="tran3">
    <type>transmission_interface/SimpleTransmission</type>
    <joint name="joint_3">
      <hardwareInterface>hardware_interface/EffortJointInterface</hardwareInterface>
    </joint>
    <actuator name="motor3">
      <hardwareInterface>hardware_interface/EffortJointInterface</hardwareInterface>
      <mechanicalReduction>1</mechanicalReduction>
    </actuator>
  </transmission>
  <transmission name="tran4">
    <type>transmission_interface/SimpleTransmission</type>
    <joint name="joint_4">
      <hardwareInterface>hardware_interface/EffortJointInterface</hardwareInterface>
    </joint>
    <actuator name="motor4">
      <hardwareInterface>hardware_interface/EffortJointInterface</hardwareInterface>
      <mechanicalReduction>1</mechanicalReduction>
    </actuator>
  </transmission>
  <transmission name="tran5">
    <type>transmission_interface/SimpleTransmission</type>
    <joint name="joint_5">
      <hardwareInterface>hardware_interface/EffortJointInterface</hardwareInterface>
    </joint>
    <actuator name="motor5">
      <hardwareInterface>hardware_interface/EffortJointInterface</hardwareInterface>
      <mechanicalReduction>1</mechanicalReduction>
    </actuator>
  </transmission>
  <transmission name="tran7">
    <type>transmission_interface/SimpleTransmission</type>
    <joint name="gripper_prismatic_joint_1">
      <hardwareInterface>hardware_interface/EffortJointInterface</hardwareInterface>
    </joint>
    <actuator name="motor7">
      <hardwareInterface>hardware_interface/EffortJointInterface</hardwareInterface>
      <mechanicalReduction>1</mechanicalReduction>
    </actuator>
  </transmission>
  <transmission name="tran8">
    <type>transmission_interface/SimpleTransmission</type>
    <joint name="gripper_prismatic_joint_2">
      <hardwareInterface>hardware_interface/EffortJointInterface</hardwareInterface>
    </joint>
    <actuator name="motor8">
      <hardwareInterface>hardware_interface/EffortJointInterface</hardwareInterface>
      <mechanicalReduction>1</mechanicalReduction>
    </actuator>
  </transmission>
  <material name="camera_aluminum">
    <color rgba="0.5 0.5 0.5 1"/>
  </material>
  <!-- camera body, with origin at bottom screw mount -->
  <joint name="camera_joint" type="fixed">
    <origin rpy="0 0 0" xyz="0.025 0 0.01"/>
    <parent link="wrist_2_link"/>
    <child link="camera_bottom_screw_frame"/>
  </joint>
  <link name="camera_bottom_screw_frame"/>
  <joint name="camera_link_joint" type="fixed">
    <origin rpy="0 0 0" xyz="0 0.0175 0.0125"/>
    <parent link="camera_bottom_screw_frame"/>
    <child link="camera_link"/>
  </joint>
  <link name="camera_link">
    <visual>
      <origin rpy="1.57079632679 0 1.57079632679" xyz="0.0149 -0.0175 0"/>
      <geometry>
        <!-- <box size="${d435_cam_width} ${d435_cam_height} ${d435_cam_depth}"/> -->
        <mesh filename="package://realsense2_description/meshes/d435.dae"/>
        <!--<mesh filename="package://realsense2_description/meshes/d435/d435.dae" />-->
      </geometry>
      <material name="camera_aluminum"/>
    </visual>
    <collision>
      <origin rpy="0 0 0" xyz="0 -0.0175 0"/>
      <geometry>
        <box size="0.02505 0.09 0.025"/>
      </geometry>
    </collision>
    <!--inertial>
         The following are not reliable values, and should not be used for modeling 
        <mass value="0.564" />
        <origin xyz="0 0 0" />
        <inertia ixx="0.003881243" ixy="0.0" ixz="0.0" iyy="0.000498940" iyz="0.0" izz="0.003879257" />
      </inertial>-->
  </link>
  <!-- camera depth joints and links -->
  <joint name="camera_depth_joint" type="fixed">
    <origin rpy="0 0 0" xyz="0 0 0"/>
    <parent link="camera_link"/>
    <child link="camera_depth_frame"/>
  </joint>
  <link name="camera_depth_frame"/>
  <joint name="camera_depth_optical_joint" type="fixed">
    <origin rpy="-1.57079632679 0 -1.57079632679" xyz="0 0 0"/>
    <parent link="camera_depth_frame"/>
    <child link="camera_depth_optical_frame"/>
  </joint>
  <link name="camera_depth_optical_frame"/>
  <!-- camera left IR joints and links -->
  <joint name="camera_left_ir_joint" type="fixed">
    <origin rpy="0 0 0" xyz="0 0.0 0"/>
    <parent link="camera_depth_frame"/>
    <child link="camera_left_ir_frame"/>
  </joint>
  <link name="camera_left_ir_frame"/>
  <joint name="camera_left_ir_optical_joint" type="fixed">
    <origin rpy="-1.57079632679 0 -1.57079632679" xyz="0 0 0"/>
    <parent link="camera_left_ir_frame"/>
    <child link="camera_left_ir_optical_frame"/>
  </joint>
  <link name="camera_left_ir_optical_frame"/>
  <!-- camera right IR joints and links -->
  <joint name="camera_right_ir_joint" type="fixed">
    <origin rpy="0 0 0" xyz="0 -0.05 0"/>
    <parent link="camera_depth_frame"/>
    <child link="camera_right_ir_frame"/>
  </joint>
  <link name="camera_right_ir_frame"/>
  <joint name="camera_right_ir_optical_joint" type="fixed">
    <origin rpy="-1.57079632679 0 -1.57079632679" xyz="0 0 0"/>
    <parent link="camera_right_ir_frame"/>
    <child link="camera_right_ir_optical_frame"/>
  </joint>
  <link name="camera_right_ir_optical_frame"/>
  <!-- camera color joints and links -->
  <joint name="camera_color_joint" type="fixed">
    <origin rpy="0 0 0" xyz="0 0.015 0"/>
    <parent link="camera_depth_frame"/>
    <child link="camera_color_frame"/>
  </joint>
  <link name="camera_color_frame"/>
  <joint name="camera_color_optical_joint" type="fixed">
    <origin rpy="-1.57079632679 0 -1.57079632679" xyz="0 0 0"/>
    <parent link="camera_color_frame"/>
    <child link="camera_color_optical_frame"/>
  </joint>
  <link name="camera_color_optical_frame"/>
  <gazebo reference="camera_link">
    <self_collide>0</self_collide>
    <enable_wind>0</enable_wind>
    <kinematic>0</kinematic>
    <gravity>1</gravity>
    <!--<mu>1</mu>-->
    <mu2>1</mu2>
    <fdir1>0 0 0</fdir1>
    <!--<slip1>0</slip1>
      <slip2>0</slip2>-->
    <kp>1e+13</kp>
    <kd>1</kd>
    <!--<max_vel>0.01</max_vel>
      <min_depth>0</min_depth>-->
    <sensor name="cameracolor" type="camera">
      <camera name="camera">
        <horizontal_fov>1.21125850088</horizontal_fov>
        <image>
          <width>640</width>
          <height>480</height>
          <format>RGB_INT8</format>
        </image>
        <clip>
          <near>0.1</near>
          <far>100</far>
        </clip>
        <noise>
          <type>gaussian</type>
          <mean>0.0</mean>
          <stddev>0.007</stddev>
        </noise>
      </camera>
      <always_on>1</always_on>
      <update_rate>30</update_rate>
      <visualize>1</visualize>
    </sensor>
    <sensor name="cameraired1" type="camera">
      <camera name="camera">
        <horizontal_fov>1.4870205227</horizontal_fov>
        <image>
          <width>1280</width>
          <height>720</height>
          <format>L_INT8</format>
        </image>
        <clip>
          <near>0.1</near>
          <far>100</far>
        </clip>
        <noise>
          <type>gaussian</type>
          <mean>0.0</mean>
          <stddev>0.05</stddev>
        </noise>
      </camera>
      <always_on>1</always_on>
      <update_rate>90</update_rate>
      <visualize>0</visualize>
    </sensor>
    <sensor name="cameraired2" type="camera">
      <camera name="camera">
        <horizontal_fov>1.4870205227</horizontal_fov>
        <image>
          <width>1280</width>
          <height>720</height>
          <format>L_INT8</format>
        </image>
        <clip>
          <near>0.1</near>
          <far>100</far>
        </clip>
        <noise>
          <type>gaussian</type>
          <mean>0.0</mean>
          <stddev>0.05</stddev>
        </noise>
      </camera>
      <always_on>1</always_on>
      <update_rate>90</update_rate>
      <visualize>0</visualize>
    </sensor>
    <sensor name="cameradepth" type="depth">
      <camera name="camera">
        <horizontal_fov>1.4870205227</horizontal_fov>
        <image>
          <width>1280</width>
          <height>720</height>
        </image>
        <clip>
          <near>0.1</near>
          <far>100</far>
        </clip>
        <noise>
          <type>gaussian</type>
          <mean>0.0</mean>
          <stddev>0.100</stddev>
        </noise>
      </camera>
      <always_on>1</always_on>
      <update_rate>90</update_rate>
      <visualize>0</visualize>
    </sensor>
  </gazebo>
  <gazebo>
    <plugin filename="librealsense_gazebo_plugin.so" name="camera">
      <prefix>camera</prefix>
      <depthUpdateRate>30.0</depthUpdateRate>
      <colorUpdateRate>30.0</colorUpdateRate>
      <infraredUpdateRate>30.0</infraredUpdateRate>
      <depthTopicName>depth/image_rect_raw</depthTopicName>
      <depthCameraInfoTopicName>depth/camera_info</depthCameraInfoTopicName>
      <colorTopicName>color/image_raw</colorTopicName>
      <colorCameraInfoTopicName>color/camera_info</colorCameraInfoTopicName>
      <infrared1TopicName>infra1/image_raw</infrared1TopicName>
      <infrared1CameraInfoTopicName>infra1/camera_info</infrared1CameraInfoTopicName>
      <infrared2TopicName>infra2/image_raw</infrared2TopicName>
      <infrared2CameraInfoTopicName>infra2/camera_info</infrared2CameraInfoTopicName>
      <colorOpticalframeName>camera_color_optical_frame</colorOpticalframeName>
      <depthOpticalframeName>camera_depth_optical_frame</depthOpticalframeName>
      <infrared1OpticalframeName>camera_left_ir_optical_frame</infrared1OpticalframeName>
      <infrared2OpticalframeName>camera_right_ir_optical_frame</infrared2OpticalframeName>
      <rangeMinDepth>0.2</rangeMinDepth>
      <rangeMaxDepth>10.0</rangeMaxDepth>
      <pointCloud>True</pointCloud>
      <pointCloudTopicName>depth/color/points</pointCloudTopicName>
      <pointCloudCutoff>0.25</pointCloudCutoff>
      <pointCloudCutoffMax>9.0</pointCloudCutoffMax>
    </plugin>
  </gazebo>
  <link name="shoulder_link">
    <visual>
      <origin rpy="0 0 0" xyz="0 0 0"/>
      <geometry>
        <mesh filename="package://demo_navi/src/meshes/arm/shoulder_link.stl"/>
      </geometry>
      <material name="">
        <color rgba="0.15 0.15 0.15 1.0"/>
      </material>
    </visual>
    <collision>
      <origin rpy="0 0 0" xyz="0 0 0"/>
      <geometry>
        <mesh filename="package://demo_navi/src/meshes/arm/shoulder_link.stl"/>
      </geometry>
    </collision>
    <inertial>
      <origin rpy="0 0 0" xyz="0 0 0"/>
      <mass value="0.1"/>
      <inertia ixx="0.01" ixy="0.0" ixz="0.0" iyy="0.01" iyz="0.0" izz="0.01"/>
    </inertial>
  </link>
  <link name="biceps_link">
    <visual>
      <origin rpy="0 0 0" xyz="0.04825 0 0.14"/>
      <geometry>
        <mesh filename="package://demo_navi/src/meshes/arm/biceps_link.stl"/>
      </geometry>
      <material name="">
        <color rgba="0.15 0.15 0.15 1.0"/>
      </material>
    </visual>
    <collision>
      <origin rpy="0 0 0" xyz="0.04825 0 0.14"/>
      <geometry>
        <mesh filename="package://demo_navi/src/meshes/arm/biceps_link.stl"/>
      </geometry>
    </collision>
    <inertial>
      <origin rpy="0 0 0" xyz="0.04825 0 0.14"/>
      <mass value="0.1"/>
      <inertia ixx="0.01" ixy="0.0" ixz="0.0" iyy="0.01" iyz="0.0" izz="0.01"/>
    </inertial>
  </link>
  <link name="forearm_link">
    <visual>
      <origin rpy="0 0 0" xyz="0 0 0.14203"/>
      <geometry>
        <mesh filename="package://demo_navi/src/meshes/arm/forearm_link.stl"/>
      </geometry>
      <material name="">
        <color rgba="0.15 0.15 0.15 1.0"/>
      </material>
    </visual>
    <collision>
      <origin rpy="0 0 0" xyz="0 0 0.14203"/>
      <geometry>
        <mesh filename="package://demo_navi/src/meshes/arm/forearm_link.stl"/>
      </geometry>
    </collision>
    <inertial>
      <origin rpy="0 0 0" xyz="0 0 0.14203"/>
      <mass value="0.1"/>
      <inertia ixx="0.01" ixy="0.0" ixz="0.0" iyy="0.01" iyz="0.0" izz="0.01"/>
    </inertial>
  </link>
  <link name="wrist_1_link">
    <visual>
      <origin rpy="0 0 0" xyz="0 0 0"/>
      <geometry>
        <mesh filename="package://demo_navi/src/meshes/arm/wrist_1_link.stl"/>
      </geometry>
      <material name="">
        <color rgba="0.15 0.15 0.15 1.0"/>
      </material>
    </visual>
    <collision>
      <origin rpy="0 0 0" xyz="0 0 0"/>
      <geometry>
        <mesh filename="package://demo_navi/src/meshes/arm/wrist_1_link.stl"/>
      </geometry>
    </collision>
    <inertial>
      <origin rpy="0 0 0" xyz="0 0 0"/>
      <mass value="0.1"/>
      <inertia ixx="0.01" ixy="0.0" ixz="0.0" iyy="0.01" iyz="0.0" izz="0.01"/>
    </inertial>
  </link>
  <link name="wrist_2_link">
    <visual>
      <origin rpy="0 0 0" xyz="0 0 0.043"/>
      <geometry>
        <mesh filename="package://demo_navi/src/meshes/arm/wrist_2_link.stl"/>
      </geometry>
      <material name="">
        <color rgba="0.15 0.15 0.15 1.0"/>
      </material>
    </visual>
    <collision>
      <origin rpy="0 0 0" xyz="0 0 0.043"/>
      <geometry>
        <mesh filename="package://demo_navi/src/meshes/arm/wrist_2_link.stl"/>
      </geometry>
    </collision>
    <inertial>
      <origin rpy="0 0 0" xyz="0 0 0.043"/>
      <mass value="0.1"/>
      <inertia ixx="0.01" ixy="0.0" ixz="0.0" iyy="0.01" iyz="0.0" izz="0.01"/>
    </inertial>
  </link>
  <link name="gripper_rail_link">
    <visual>
      <origin rpy="0 0 1.57" xyz="0 0 0"/>
      <geometry>
        <mesh filename="package://demo_navi/src/meshes/arm/gripper_rail_link.stl"/>
      </geometry>
      <material name="">
        <color rgba="0.15 0.15 0.15 1.0"/>
      </material>
    </visual>
    <collision>
      <origin rpy="0 0 1.57" xyz="0 0 0"/>
      <geometry>
        <mesh filename="package://demo_navi/src/meshes/arm/gripper_rail_link.stl"/>
      </geometry>
    </collision>
    <inertial>
      <origin rpy="0 0 1.57" xyz="0 0 0"/>
      <mass value="0.1"/>
      <inertia ixx="0.01" ixy="0.0" ixz="0.0" iyy="0.01" iyz="0.0" izz="0.01"/>
    </inertial>
  </link>
  <link name="gripper_aux_link">
      </link>
  <link name="gripper_1_link">
    <visual>
      <origin rpy="0 0 1.57" xyz="0 -0.0007 0"/>
      <geometry>
        <mesh filename="package://demo_navi/src/meshes/arm/gripper_hand_fixed_link.stl"/>
      </geometry>
      <material name="">
        <color rgba="0.15 0.15 0.15 1.0"/>
      </material>
    </visual>
    <collision>
      <origin rpy="0 0 1.57" xyz="0 -0.0007 0"/>
      <geometry>
        <mesh filename="package://demo_navi/src/meshes/arm/gripper_hand_fixed_link.stl"/>
      </geometry>
    </collision>
    <inertial>
      <origin rpy="0 0 1.57" xyz="0 -0.0007 0"/>
      <mass value="0.1"/>
      <inertia ixx="0.01" ixy="0.0" ixz="0.0" iyy="0.01" iyz="0.0" izz="0.01"/>
    </inertial>
  </link>
  <link name="gripper_2_link">
    <visual>
      <origin rpy="0 0 -1.57" xyz="0 0.0007 0"/>
      <geometry>
        <mesh filename="package://demo_navi/src/meshes/arm/gripper_hand_fixed_link.stl"/>
      </geometry>
      <material name="">
        <color rgba="0.15 0.15 0.15 1.0"/>
      </material>
    </visual>
    <collision>
      <origin rpy="0 0 -1.57" xyz="0 0.0007 0"/>
      <geometry>
        <mesh filename="package://demo_navi/src/meshes/arm/gripper_hand_fixed_link.stl"/>
      </geometry>
    </collision>
    <inertial>
      <origin rpy="0 0 -1.57" xyz="0 0.0007 0"/>
      <mass value="0.1"/>
      <inertia ixx="0.01" ixy="0.0" ixz="0.0" iyy="0.01" iyz="0.0" izz="0.01"/>
    </inertial>
  </link>
  <!-- joints -->
  <joint name="joint_1" type="revolute">
    <origin rpy="0 0 0" xyz="0 0 0.15"/>
    <parent link="base_link"/>
    <child link="shoulder_link"/>
    <axis xyz="0 0 1"/>
    <limit effort="100" lower="-3.1415" upper="3.1415" velocity="1.0"/>
  </joint>
  <joint name="joint_2" type="revolute">
    <!--origin xyz="0.04825 0 0.14203" rpy="0 0 0" /-->
    <origin rpy="0 0 0" xyz="0 0 0"/>
    <parent link="shoulder_link"/>
    <child link="biceps_link"/>
    <axis xyz="0 1 0"/>
    <limit effort="100" lower="-1.571" upper="1.571" velocity="1.0"/>
  </joint>
  <joint name="joint_3" type="revolute">
    <origin rpy="0 1.571 0" xyz="0.04825 0 0.14203"/>
    <parent link="biceps_link"/>
    <child link="forearm_link"/>
    <axis xyz="0 1 0"/>
    <limit effort="100" lower="-1.571" upper="1.571" velocity="1.0"/>
  </joint>
  <joint name="joint_4" type="revolute">
    <origin rpy="0 0 0" xyz="0 0 0.14203"/>
    <parent link="forearm_link"/>
    <child link="wrist_1_link"/>
    <axis xyz="0 1 0"/>
    <limit effort="100" lower="-1.745" upper="1.745" velocity="1.0"/>
  </joint>
  <joint name="joint_5" type="revolute">
    <origin rpy="0 0 0" xyz="0 0 0.0715"/>
    <parent link="wrist_1_link"/>
    <child link="wrist_2_link"/>
    <axis xyz="0 0 1"/>
    <limit effort="100" lower="-2.617" upper="2.617" velocity="1.0"/>
  </joint>
  <joint name="joint_6" type="fixed">
    <origin rpy="0 0 0" xyz="0 0 0.043"/>
    <parent link="wrist_2_link"/>
    <child link="gripper_rail_link"/>
    <axis xyz="0 0 1"/>
    <limit effort="100" lower="-0.31" upper="0.1" velocity="0.5"/>
  </joint>
  <joint name="gripper_revolute_joint" type="revolute">
    <origin rpy="0 0 0" xyz="0 0 0"/>
    <parent link="gripper_rail_link"/>
    <child link="gripper_aux_link"/>
    <axis xyz="0 0 1"/>
    <limit effort="10000" lower="0" upper="2.6" velocity="0.5"/>
  </joint>
  <joint name="gripper_prismatic_joint_1" type="prismatic">
    <origin rpy="0 0 0" xyz="0 0 0"/>
    <parent link="gripper_rail_link"/>
    <child link="gripper_1_link"/>
    <axis xyz="0 -1 0"/>
    <limit effort="10000" lower="0" upper="0.027" velocity="0.5"/>
  </joint>
  <joint name="gripper_prismatic_joint_2" type="prismatic">
    <origin rpy="0 0 0" xyz="0 0 0"/>
    <parent link="gripper_rail_link"/>
    <child link="gripper_2_link"/>
    <axis xyz="0 1 0"/>
    <limit effort="10000" lower="0" upper="0.027" velocity="0.5"/>
  </joint>
  <link name="base_footprint"/>
  <link name="imu_link"/>
  <link name="base_link">
    <inertial>
      <origin rpy="0 0 0" xyz="-0.147 0 0.05"/>
      <mass value="15"/>
      <inertia ixx="15.0" ixy="0" ixz="0" iyy="15.0" iyz="0" izz="9.0"/>
    </inertial>
    <visual>
      <origin rpy="0 0 0" xyz="0 0 0"/>
      <geometry>
        <mesh filename="package://demo_navi/src/meshes/base_link.stl"/>
      </geometry>
      <material name="base_material">
        <color rgba="0.098039 0.098039 0.098039 1"/>
      </material>
    </visual>
    <collision>
      <origin rpy="0 0 0" xyz="0 0 0"/>
      <geometry>
        <mesh filename="package://demo_navi/src/meshes/base_link.stl"/>
      </geometry>
    </collision>
  </link>
  <joint name="base_joint" type="fixed">
    <parent link="base_footprint"/>
    <child link="base_link"/>
    <origin xyz="0.144 0 0"/>
  </joint>
  <joint name="imu_joint" type="fixed">
    <parent link="base_footprint"/>
    <child link="imu_link"/>
    <origin xyz="-0.145 0 0.091"/>
  </joint>
  <link name="rim_left_link">
    <inertial>
      <origin xyz="0 0 0"/>
      <mass value="0.5"/>
      <inertia ixx="0.7" ixy="0" ixz="0" iyy="0.7" iyz="0" izz="0.8"/>
    </inertial>
    <visual>
      <geometry>
        <mesh filename="package://demo_navi/src/meshes/rim.stl"/>
      </geometry>
      <material name="rim_left_material">
        <color rgba="1.3 0 0 1"/>
      </material>
    </visual>
    <collision>
      <geometry>
        <mesh filename="package://demo_navi/src/meshes/rim.stl"/>
      </geometry>
    </collision>
  </link>
  <joint name="rim_left_joint" type="continuous">
    <parent link="base_link"/>
    <child link="rim_left_link"/>
    <axis xyz="1 0 0"/>
    <origin rpy="0 0 -2.0944" xyz="-0.0267 0.214 0.04"/>
    <limit effort="100000000" velocity="10"/>
  </joint>
  <link name="roller_s_rim_left_link">
    <inertial>
      <mass value="0.1"/>
      <inertia ixx="6.8e-01" ixy="0" ixz="0" iyy="6.8e-01" iyz="0" izz="0.0101"/>
    </inertial>
    <visual>
      <geometry>
        <mesh filename="package://demo_navi/src/meshes/roller.stl"/>
      </geometry>
      <material name="roller_material">
        <color rgba="0.1 0.1 0.1 1"/>
      </material>
    </visual>
    <collision>
      <geometry>
        <mesh filename="package://demo_navi/src/meshes/roller.stl"/>
      </geometry>
    </collision>
  </link>
  <joint name="roller_s_rim_left_joint" type="continuous">
    <parent link="rim_left_link"/>
    <child link="roller_s_rim_left_link"/>
    <axis xyz="0 1 0"/>
    <origin rpy="0 0 0" xyz="0.0153 0 -0.0266"/>
    <limit effort="100000000" velocity="10"/>
  </joint>
  <gazebo reference="roller_s_rim_left_link">
    <!--<mu1>50.0</mu1>
  			<mu2>25.0</mu2>
      		<kp  value="10000000000.0" />
      		<kd  value="10000000000.0" /-->
    <dampingFactor>10</dampingFactor>
    <minDepth>1</minDepth>
    <material>Gazebo/Grey</material>
  </gazebo>
  <!--<gazebo reference="roller_${name}_rim_${parent}_joint">
    <selfCollide>False</selfCollide>
    <dampingFactor>10</dampingFactor>
    <minDepth>0.001</minDepth>
  </gazebo>-->
  <link name="roller_nw_rim_left_link">
    <inertial>
      <mass value="0.1"/>
      <inertia ixx="6.8e-01" ixy="0" ixz="0" iyy="6.8e-01" iyz="0" izz="0.0101"/>
    </inertial>
    <visual>
      <geometry>
        <mesh filename="package://demo_navi/src/meshes/roller.stl"/>
      </geometry>
      <material name="roller_material">
        <color rgba="0.1 0.1 0.1 1"/>
      </material>
    </visual>
    <collision>
      <geometry>
        <mesh filename="package://demo_navi/src/meshes/roller.stl"/>
      </geometry>
    </collision>
  </link>
  <joint name="roller_nw_rim_left_joint" type="continuous">
    <parent link="rim_left_link"/>
    <child link="roller_nw_rim_left_link"/>
    <axis xyz="0 1 0"/>
    <origin rpy="1.0472 0 0" xyz="0.015 -0.0231 0.0131"/>
    <limit effort="100000000" velocity="10"/>
  </joint>
  <gazebo reference="roller_nw_rim_left_link">
    <!--<mu1>50.0</mu1>
  			<mu2>25.0</mu2>
      		<kp  value="10000000000.0" />
      		<kd  value="10000000000.0" /-->
    <dampingFactor>10</dampingFactor>
    <minDepth>1</minDepth>
    <material>Gazebo/Grey</material>
  </gazebo>
  <!--<gazebo reference="roller_${name}_rim_${parent}_joint">
    <selfCollide>False</selfCollide>
    <dampingFactor>10</dampingFactor>
    <minDepth>0.001</minDepth>
  </gazebo>-->
  <link name="roller_ne_rim_left_link">
    <inertial>
      <mass value="0.1"/>
      <inertia ixx="6.8e-01" ixy="0" ixz="0" iyy="6.8e-01" iyz="0" izz="0.0101"/>
    </inertial>
    <visual>
      <geometry>
        <mesh filename="package://demo_navi/src/meshes/roller.stl"/>
      </geometry>
      <material name="roller_material">
        <color rgba="0.1 0.1 0.1 1"/>
      </material>
    </visual>
    <collision>
      <geometry>
        <mesh filename="package://demo_navi/src/meshes/roller.stl"/>
      </geometry>
    </collision>
  </link>
  <joint name="roller_ne_rim_left_joint" type="continuous">
    <parent link="rim_left_link"/>
    <child link="roller_ne_rim_left_link"/>
    <axis xyz="0 1 0"/>
    <origin rpy="-1.0472 0 0" xyz="0.015 0.0231 0.0135"/>
    <limit effort="100000000" velocity="10"/>
  </joint>
  <gazebo reference="roller_ne_rim_left_link">
    <!--<mu1>50.0</mu1>
  			<mu2>25.0</mu2>
      		<kp  value="10000000000.0" />
      		<kd  value="10000000000.0" /-->
    <dampingFactor>10</dampingFactor>
    <minDepth>1</minDepth>
    <material>Gazebo/Grey</material>
  </gazebo>
  <!--<gazebo reference="roller_${name}_rim_${parent}_joint">
    <selfCollide>False</selfCollide>
    <dampingFactor>10</dampingFactor>
    <minDepth>0.001</minDepth>
  </gazebo>-->
  <link name="roller_sw_rim_left_link">
    <inertial>
      <mass value="0.1"/>
      <inertia ixx="6.8e-01" ixy="0" ixz="0" iyy="6.8e-01" iyz="0" izz="0.0101"/>
    </inertial>
    <visual>
      <geometry>
        <mesh filename="package://demo_navi/src/meshes/roller.stl"/>
      </geometry>
      <material name="roller_material">
        <color rgba="0.1 0.1 0.1 1"/>
      </material>
    </visual>
    <collision>
      <geometry>
        <mesh filename="package://demo_navi/src/meshes/roller.stl"/>
      </geometry>
    </collision>
  </link>
  <joint name="roller_sw_rim_left_joint" type="continuous">
    <parent link="rim_left_link"/>
    <child link="roller_sw_rim_left_link"/>
    <axis xyz="0 1 0"/>
    <origin rpy="1.0472 0 0" xyz="-0.0146 0.023 -0.0133"/>
    <limit effort="100000000" velocity="10"/>
  </joint>
  <gazebo reference="roller_sw_rim_left_link">
    <!--<mu1>50.0</mu1>
  			<mu2>25.0</mu2>
      		<kp  value="10000000000.0" />
      		<kd  value="10000000000.0" /-->
    <dampingFactor>10</dampingFactor>
    <minDepth>1</minDepth>
    <material>Gazebo/Grey</material>
  </gazebo>
  <!--<gazebo reference="roller_${name}_rim_${parent}_joint">
    <selfCollide>False</selfCollide>
    <dampingFactor>10</dampingFactor>
    <minDepth>0.001</minDepth>
  </gazebo>-->
  <link name="roller_n_rim_left_link">
    <inertial>
      <mass value="0.1"/>
      <inertia ixx="6.8e-01" ixy="0" ixz="0" iyy="6.8e-01" iyz="0" izz="0.0101"/>
    </inertial>
    <visual>
      <geometry>
        <mesh filename="package://demo_navi/src/meshes/roller.stl"/>
      </geometry>
      <material name="roller_material">
        <color rgba="0.1 0.1 0.1 1"/>
      </material>
    </visual>
    <collision>
      <geometry>
        <mesh filename="package://demo_navi/src/meshes/roller.stl"/>
      </geometry>
    </collision>
  </link>
  <joint name="roller_n_rim_left_joint" type="continuous">
    <parent link="rim_left_link"/>
    <child link="roller_n_rim_left_link"/>
    <axis xyz="0 1 0"/>
    <origin rpy="0 0 0" xyz="-0.0146 0 0.0268"/>
    <limit effort="100000000" velocity="10"/>
  </joint>
  <gazebo reference="roller_n_rim_left_link">
    <!--<mu1>50.0</mu1>
  			<mu2>25.0</mu2>
      		<kp  value="10000000000.0" />
      		<kd  value="10000000000.0" /-->
    <dampingFactor>10</dampingFactor>
    <minDepth>1</minDepth>
    <material>Gazebo/Grey</material>
  </gazebo>
  <!--<gazebo reference="roller_${name}_rim_${parent}_joint">
    <selfCollide>False</selfCollide>
    <dampingFactor>10</dampingFactor>
    <minDepth>0.001</minDepth>
  </gazebo>-->
  <link name="roller_se_rim_left_link">
    <inertial>
      <mass value="0.1"/>
      <inertia ixx="6.8e-01" ixy="0" ixz="0" iyy="6.8e-01" iyz="0" izz="0.0101"/>
    </inertial>
    <visual>
      <geometry>
        <mesh filename="package://demo_navi/src/meshes/roller.stl"/>
      </geometry>
      <material name="roller_material">
        <color rgba="0.1 0.1 0.1 1"/>
      </material>
    </visual>
    <collision>
      <geometry>
        <mesh filename="package://demo_navi/src/meshes/roller.stl"/>
      </geometry>
    </collision>
  </link>
  <joint name="roller_se_rim_left_joint" type="continuous">
    <parent link="rim_left_link"/>
    <child link="roller_se_rim_left_link"/>
    <axis xyz="0 1 0"/>
    <origin rpy="-1.0472 0 0" xyz="-0.0146 -0.023 -0.0133"/>
    <limit effort="100000000" velocity="10"/>
  </joint>
  <gazebo reference="roller_se_rim_left_link">
    <!--<mu1>50.0</mu1>
  			<mu2>25.0</mu2>
      		<kp  value="10000000000.0" />
      		<kd  value="10000000000.0" /-->
    <dampingFactor>10</dampingFactor>
    <minDepth>1</minDepth>
    <material>Gazebo/Grey</material>
  </gazebo>
  <!--<gazebo reference="roller_${name}_rim_${parent}_joint">
    <selfCollide>False</selfCollide>
    <dampingFactor>10</dampingFactor>
    <minDepth>0.001</minDepth>
  </gazebo>-->
  <transmission name="rim_left_transmission">
    <type>transmission_interface/SimpleTransmission</type>
    <joint name="rim_left_joint">
      <hardwareInterface>hardware_interface/VelocityJointInterface</hardwareInterface>
    </joint>
    <actuator name="rim_left_motor">
      <hardwareInterface>hardware_interface/VelocityJointInterface</hardwareInterface>
      <mechanicalReduction>1</mechanicalReduction>
    </actuator>
  </transmission>
  <gazebo reference="rim_left_link">
    <!--mu1>50.0</mu1>
  				<mu2>25.0</mu2-->
    <!--kp  value="10000000.0" />
      			<selfCollide>False</selfCollide>
      			<kd  value="10000000.0" /-->
    <dampingFactor>10</dampingFactor>
    <minDepth>1</minDepth>
  </gazebo>
  <link name="rim_back_link">
    <inertial>
      <origin xyz="0 0 0"/>
      <mass value="0.5"/>
      <inertia ixx="0.7" ixy="0" ixz="0" iyy="0.7" iyz="0" izz="0.8"/>
    </inertial>
    <visual>
      <geometry>
        <mesh filename="package://demo_navi/src/meshes/rim.stl"/>
      </geometry>
      <material name="rim_back_material">
        <color rgba="1.3 0 0 1"/>
      </material>
    </visual>
    <collision>
      <geometry>
        <mesh filename="package://demo_navi/src/meshes/rim.stl"/>
      </geometry>
    </collision>
  </link>
  <joint name="rim_back_joint" type="continuous">
    <parent link="base_link"/>
    <child link="rim_back_link"/>
    <axis xyz="1 0 0"/>
    <origin rpy="0 0 0" xyz="-0.397 0 0.04"/>
    <limit effort="100000000" velocity="10"/>
  </joint>
  <link name="roller_s_rim_back_link">
    <inertial>
      <mass value="0.1"/>
      <inertia ixx="6.8e-01" ixy="0" ixz="0" iyy="6.8e-01" iyz="0" izz="0.0101"/>
    </inertial>
    <visual>
      <geometry>
        <mesh filename="package://demo_navi/src/meshes/roller.stl"/>
      </geometry>
      <material name="roller_material">
        <color rgba="0.1 0.1 0.1 1"/>
      </material>
    </visual>
    <collision>
      <geometry>
        <mesh filename="package://demo_navi/src/meshes/roller.stl"/>
      </geometry>
    </collision>
  </link>
  <joint name="roller_s_rim_back_joint" type="continuous">
    <parent link="rim_back_link"/>
    <child link="roller_s_rim_back_link"/>
    <axis xyz="0 1 0"/>
    <origin rpy="0 0 0" xyz="0.0153 0 -0.0266"/>
    <limit effort="100000000" velocity="10"/>
  </joint>
  <gazebo reference="roller_s_rim_back_link">
    <!--<mu1>50.0</mu1>
  			<mu2>25.0</mu2>
      		<kp  value="10000000000.0" />
      		<kd  value="10000000000.0" /-->
    <dampingFactor>10</dampingFactor>
    <minDepth>1</minDepth>
    <material>Gazebo/Grey</material>
  </gazebo>
  <!--<gazebo reference="roller_${name}_rim_${parent}_joint">
    <selfCollide>False</selfCollide>
    <dampingFactor>10</dampingFactor>
    <minDepth>0.001</minDepth>
  </gazebo>-->
  <link name="roller_nw_rim_back_link">
    <inertial>
      <mass value="0.1"/>
      <inertia ixx="6.8e-01" ixy="0" ixz="0" iyy="6.8e-01" iyz="0" izz="0.0101"/>
    </inertial>
    <visual>
      <geometry>
        <mesh filename="package://demo_navi/src/meshes/roller.stl"/>
      </geometry>
      <material name="roller_material">
        <color rgba="0.1 0.1 0.1 1"/>
      </material>
    </visual>
    <collision>
      <geometry>
        <mesh filename="package://demo_navi/src/meshes/roller.stl"/>
      </geometry>
    </collision>
  </link>
  <joint name="roller_nw_rim_back_joint" type="continuous">
    <parent link="rim_back_link"/>
    <child link="roller_nw_rim_back_link"/>
    <axis xyz="0 1 0"/>
    <origin rpy="1.0472 0 0" xyz="0.015 -0.0231 0.0131"/>
    <limit effort="100000000" velocity="10"/>
  </joint>
  <gazebo reference="roller_nw_rim_back_link">
    <!--<mu1>50.0</mu1>
  			<mu2>25.0</mu2>
      		<kp  value="10000000000.0" />
      		<kd  value="10000000000.0" /-->
    <dampingFactor>10</dampingFactor>
    <minDepth>1</minDepth>
    <material>Gazebo/Grey</material>
  </gazebo>
  <!--<gazebo reference="roller_${name}_rim_${parent}_joint">
    <selfCollide>False</selfCollide>
    <dampingFactor>10</dampingFactor>
    <minDepth>0.001</minDepth>
  </gazebo>-->
  <link name="roller_ne_rim_back_link">
    <inertial>
      <mass value="0.1"/>
      <inertia ixx="6.8e-01" ixy="0" ixz="0" iyy="6.8e-01" iyz="0" izz="0.0101"/>
    </inertial>
    <visual>
      <geometry>
        <mesh filename="package://demo_navi/src/meshes/roller.stl"/>
      </geometry>
      <material name="roller_material">
        <color rgba="0.1 0.1 0.1 1"/>
      </material>
    </visual>
    <collision>
      <geometry>
        <mesh filename="package://demo_navi/src/meshes/roller.stl"/>
      </geometry>
    </collision>
  </link>
  <joint name="roller_ne_rim_back_joint" type="continuous">
    <parent link="rim_back_link"/>
    <child link="roller_ne_rim_back_link"/>
    <axis xyz="0 1 0"/>
    <origin rpy="-1.0472 0 0" xyz="0.015 0.0231 0.0135"/>
    <limit effort="100000000" velocity="10"/>
  </joint>
  <gazebo reference="roller_ne_rim_back_link">
    <!--<mu1>50.0</mu1>
  			<mu2>25.0</mu2>
      		<kp  value="10000000000.0" />
      		<kd  value="10000000000.0" /-->
    <dampingFactor>10</dampingFactor>
    <minDepth>1</minDepth>
    <material>Gazebo/Grey</material>
  </gazebo>
  <!--<gazebo reference="roller_${name}_rim_${parent}_joint">
    <selfCollide>False</selfCollide>
    <dampingFactor>10</dampingFactor>
    <minDepth>0.001</minDepth>
  </gazebo>-->
  <link name="roller_sw_rim_back_link">
    <inertial>
      <mass value="0.1"/>
      <inertia ixx="6.8e-01" ixy="0" ixz="0" iyy="6.8e-01" iyz="0" izz="0.0101"/>
    </inertial>
    <visual>
      <geometry>
        <mesh filename="package://demo_navi/src/meshes/roller.stl"/>
      </geometry>
      <material name="roller_material">
        <color rgba="0.1 0.1 0.1 1"/>
      </material>
    </visual>
    <collision>
      <geometry>
        <mesh filename="package://demo_navi/src/meshes/roller.stl"/>
      </geometry>
    </collision>
  </link>
  <joint name="roller_sw_rim_back_joint" type="continuous">
    <parent link="rim_back_link"/>
    <child link="roller_sw_rim_back_link"/>
    <axis xyz="0 1 0"/>
    <origin rpy="1.0472 0 0" xyz="-0.0146 0.023 -0.0133"/>
    <limit effort="100000000" velocity="10"/>
  </joint>
  <gazebo reference="roller_sw_rim_back_link">
    <!--<mu1>50.0</mu1>
  			<mu2>25.0</mu2>
      		<kp  value="10000000000.0" />
      		<kd  value="10000000000.0" /-->
    <dampingFactor>10</dampingFactor>
    <minDepth>1</minDepth>
    <material>Gazebo/Grey</material>
  </gazebo>
  <!--<gazebo reference="roller_${name}_rim_${parent}_joint">
    <selfCollide>False</selfCollide>
    <dampingFactor>10</dampingFactor>
    <minDepth>0.001</minDepth>
  </gazebo>-->
  <link name="roller_n_rim_back_link">
    <inertial>
      <mass value="0.1"/>
      <inertia ixx="6.8e-01" ixy="0" ixz="0" iyy="6.8e-01" iyz="0" izz="0.0101"/>
    </inertial>
    <visual>
      <geometry>
        <mesh filename="package://demo_navi/src/meshes/roller.stl"/>
      </geometry>
      <material name="roller_material">
        <color rgba="0.1 0.1 0.1 1"/>
      </material>
    </visual>
    <collision>
      <geometry>
        <mesh filename="package://demo_navi/src/meshes/roller.stl"/>
      </geometry>
    </collision>
  </link>
  <joint name="roller_n_rim_back_joint" type="continuous">
    <parent link="rim_back_link"/>
    <child link="roller_n_rim_back_link"/>
    <axis xyz="0 1 0"/>
    <origin rpy="0 0 0" xyz="-0.0146 0 0.0268"/>
    <limit effort="100000000" velocity="10"/>
  </joint>
  <gazebo reference="roller_n_rim_back_link">
    <!--<mu1>50.0</mu1>
  			<mu2>25.0</mu2>
      		<kp  value="10000000000.0" />
      		<kd  value="10000000000.0" /-->
    <dampingFactor>10</dampingFactor>
    <minDepth>1</minDepth>
    <material>Gazebo/Grey</material>
  </gazebo>
  <!--<gazebo reference="roller_${name}_rim_${parent}_joint">
    <selfCollide>False</selfCollide>
    <dampingFactor>10</dampingFactor>
    <minDepth>0.001</minDepth>
  </gazebo>-->
  <link name="roller_se_rim_back_link">
    <inertial>
      <mass value="0.1"/>
      <inertia ixx="6.8e-01" ixy="0" ixz="0" iyy="6.8e-01" iyz="0" izz="0.0101"/>
    </inertial>
    <visual>
      <geometry>
        <mesh filename="package://demo_navi/src/meshes/roller.stl"/>
      </geometry>
      <material name="roller_material">
        <color rgba="0.1 0.1 0.1 1"/>
      </material>
    </visual>
    <collision>
      <geometry>
        <mesh filename="package://demo_navi/src/meshes/roller.stl"/>
      </geometry>
    </collision>
  </link>
  <joint name="roller_se_rim_back_joint" type="continuous">
    <parent link="rim_back_link"/>
    <child link="roller_se_rim_back_link"/>
    <axis xyz="0 1 0"/>
    <origin rpy="-1.0472 0 0" xyz="-0.0146 -0.023 -0.0133"/>
    <limit effort="100000000" velocity="10"/>
  </joint>
  <gazebo reference="roller_se_rim_back_link">
    <!--<mu1>50.0</mu1>
  			<mu2>25.0</mu2>
      		<kp  value="10000000000.0" />
      		<kd  value="10000000000.0" /-->
    <dampingFactor>10</dampingFactor>
    <minDepth>1</minDepth>
    <material>Gazebo/Grey</material>
  </gazebo>
  <!--<gazebo reference="roller_${name}_rim_${parent}_joint">
    <selfCollide>False</selfCollide>
    <dampingFactor>10</dampingFactor>
    <minDepth>0.001</minDepth>
  </gazebo>-->
  <transmission name="rim_back_transmission">
    <type>transmission_interface/SimpleTransmission</type>
    <joint name="rim_back_joint">
      <hardwareInterface>hardware_interface/VelocityJointInterface</hardwareInterface>
    </joint>
    <actuator name="rim_back_motor">
      <hardwareInterface>hardware_interface/VelocityJointInterface</hardwareInterface>
      <mechanicalReduction>1</mechanicalReduction>
    </actuator>
  </transmission>
  <gazebo reference="rim_back_link">
    <!--mu1>50.0</mu1>
  				<mu2>25.0</mu2-->
    <!--kp  value="10000000.0" />
      			<selfCollide>False</selfCollide>
      			<kd  value="10000000.0" /-->
    <dampingFactor>10</dampingFactor>
    <minDepth>1</minDepth>
  </gazebo>
  <link name="rim_right_link">
    <inertial>
      <origin xyz="0 0 0"/>
      <mass value="0.5"/>
      <inertia ixx="0.7" ixy="0" ixz="0" iyy="0.7" iyz="0" izz="0.8"/>
    </inertial>
    <visual>
      <geometry>
        <mesh filename="package://demo_navi/src/meshes/rim.stl"/>
      </geometry>
      <material name="rim_right_material">
        <color rgba="1.3 0 0 1"/>
      </material>
    </visual>
    <collision>
      <geometry>
        <mesh filename="package://demo_navi/src/meshes/rim.stl"/>
      </geometry>
    </collision>
  </link>
  <joint name="rim_right_joint" type="continuous">
    <parent link="base_link"/>
    <child link="rim_right_link"/>
    <axis xyz="1 0 0"/>
    <origin rpy="0 0 2.0944" xyz="-0.0267 -0.214 0.04"/>
    <limit effort="100000000" velocity="10"/>
  </joint>
  <link name="roller_s_rim_right_link">
    <inertial>
      <mass value="0.1"/>
      <inertia ixx="6.8e-01" ixy="0" ixz="0" iyy="6.8e-01" iyz="0" izz="0.0101"/>
    </inertial>
    <visual>
      <geometry>
        <mesh filename="package://demo_navi/src/meshes/roller.stl"/>
      </geometry>
      <material name="roller_material">
        <color rgba="0.1 0.1 0.1 1"/>
      </material>
    </visual>
    <collision>
      <geometry>
        <mesh filename="package://demo_navi/src/meshes/roller.stl"/>
      </geometry>
    </collision>
  </link>
  <joint name="roller_s_rim_right_joint" type="continuous">
    <parent link="rim_right_link"/>
    <child link="roller_s_rim_right_link"/>
    <axis xyz="0 1 0"/>
    <origin rpy="0 0 0" xyz="0.0153 0 -0.0266"/>
    <limit effort="100000000" velocity="10"/>
  </joint>
  <gazebo reference="roller_s_rim_right_link">
    <!--<mu1>50.0</mu1>
  			<mu2>25.0</mu2>
      		<kp  value="10000000000.0" />
      		<kd  value="10000000000.0" /-->
    <dampingFactor>10</dampingFactor>
    <minDepth>1</minDepth>
    <material>Gazebo/Grey</material>
  </gazebo>
  <!--<gazebo reference="roller_${name}_rim_${parent}_joint">
    <selfCollide>False</selfCollide>
    <dampingFactor>10</dampingFactor>
    <minDepth>0.001</minDepth>
  </gazebo>-->
  <link name="roller_nw_rim_right_link">
    <inertial>
      <mass value="0.1"/>
      <inertia ixx="6.8e-01" ixy="0" ixz="0" iyy="6.8e-01" iyz="0" izz="0.0101"/>
    </inertial>
    <visual>
      <geometry>
        <mesh filename="package://demo_navi/src/meshes/roller.stl"/>
      </geometry>
      <material name="roller_material">
        <color rgba="0.1 0.1 0.1 1"/>
      </material>
    </visual>
    <collision>
      <geometry>
        <mesh filename="package://demo_navi/src/meshes/roller.stl"/>
      </geometry>
    </collision>
  </link>
  <joint name="roller_nw_rim_right_joint" type="continuous">
    <parent link="rim_right_link"/>
    <child link="roller_nw_rim_right_link"/>
    <axis xyz="0 1 0"/>
    <origin rpy="1.0472 0 0" xyz="0.015 -0.0231 0.0131"/>
    <limit effort="100000000" velocity="10"/>
  </joint>
  <gazebo reference="roller_nw_rim_right_link">
    <!--<mu1>50.0</mu1>
  			<mu2>25.0</mu2>
      		<kp  value="10000000000.0" />
      		<kd  value="10000000000.0" /-->
    <dampingFactor>10</dampingFactor>
    <minDepth>1</minDepth>
    <material>Gazebo/Grey</material>
  </gazebo>
  <!--<gazebo reference="roller_${name}_rim_${parent}_joint">
    <selfCollide>False</selfCollide>
    <dampingFactor>10</dampingFactor>
    <minDepth>0.001</minDepth>
  </gazebo>-->
  <link name="roller_ne_rim_right_link">
    <inertial>
      <mass value="0.1"/>
      <inertia ixx="6.8e-01" ixy="0" ixz="0" iyy="6.8e-01" iyz="0" izz="0.0101"/>
    </inertial>
    <visual>
      <geometry>
        <mesh filename="package://demo_navi/src/meshes/roller.stl"/>
      </geometry>
      <material name="roller_material">
        <color rgba="0.1 0.1 0.1 1"/>
      </material>
    </visual>
    <collision>
      <geometry>
        <mesh filename="package://demo_navi/src/meshes/roller.stl"/>
      </geometry>
    </collision>
  </link>
  <joint name="roller_ne_rim_right_joint" type="continuous">
    <parent link="rim_right_link"/>
    <child link="roller_ne_rim_right_link"/>
    <axis xyz="0 1 0"/>
    <origin rpy="-1.0472 0 0" xyz="0.015 0.0231 0.0135"/>
    <limit effort="100000000" velocity="10"/>
  </joint>
  <gazebo reference="roller_ne_rim_right_link">
    <!--<mu1>50.0</mu1>
  			<mu2>25.0</mu2>
      		<kp  value="10000000000.0" />
      		<kd  value="10000000000.0" /-->
    <dampingFactor>10</dampingFactor>
    <minDepth>1</minDepth>
    <material>Gazebo/Grey</material>
  </gazebo>
  <!--<gazebo reference="roller_${name}_rim_${parent}_joint">
    <selfCollide>False</selfCollide>
    <dampingFactor>10</dampingFactor>
    <minDepth>0.001</minDepth>
  </gazebo>-->
  <link name="roller_sw_rim_right_link">
    <inertial>
      <mass value="0.1"/>
      <inertia ixx="6.8e-01" ixy="0" ixz="0" iyy="6.8e-01" iyz="0" izz="0.0101"/>
    </inertial>
    <visual>
      <geometry>
        <mesh filename="package://demo_navi/src/meshes/roller.stl"/>
      </geometry>
      <material name="roller_material">
        <color rgba="0.1 0.1 0.1 1"/>
      </material>
    </visual>
    <collision>
      <geometry>
        <mesh filename="package://demo_navi/src/meshes/roller.stl"/>
      </geometry>
    </collision>
  </link>
  <joint name="roller_sw_rim_right_joint" type="continuous">
    <parent link="rim_right_link"/>
    <child link="roller_sw_rim_right_link"/>
    <axis xyz="0 1 0"/>
    <origin rpy="1.0472 0 0" xyz="-0.0146 0.023 -0.0133"/>
    <limit effort="100000000" velocity="10"/>
  </joint>
  <gazebo reference="roller_sw_rim_right_link">
    <!--<mu1>50.0</mu1>
  			<mu2>25.0</mu2>
      		<kp  value="10000000000.0" />
      		<kd  value="10000000000.0" /-->
    <dampingFactor>10</dampingFactor>
    <minDepth>1</minDepth>
    <material>Gazebo/Grey</material>
  </gazebo>
  <!--<gazebo reference="roller_${name}_rim_${parent}_joint">
    <selfCollide>False</selfCollide>
    <dampingFactor>10</dampingFactor>
    <minDepth>0.001</minDepth>
  </gazebo>-->
  <link name="roller_n_rim_right_link">
    <inertial>
      <mass value="0.1"/>
      <inertia ixx="6.8e-01" ixy="0" ixz="0" iyy="6.8e-01" iyz="0" izz="0.0101"/>
    </inertial>
    <visual>
      <geometry>
        <mesh filename="package://demo_navi/src/meshes/roller.stl"/>
      </geometry>
      <material name="roller_material">
        <color rgba="0.1 0.1 0.1 1"/>
      </material>
    </visual>
    <collision>
      <geometry>
        <mesh filename="package://demo_navi/src/meshes/roller.stl"/>
      </geometry>
    </collision>
  </link>
  <joint name="roller_n_rim_right_joint" type="continuous">
    <parent link="rim_right_link"/>
    <child link="roller_n_rim_right_link"/>
    <axis xyz="0 1 0"/>
    <origin rpy="0 0 0" xyz="-0.0146 0 0.0268"/>
    <limit effort="100000000" velocity="10"/>
  </joint>
  <gazebo reference="roller_n_rim_right_link">
    <!--<mu1>50.0</mu1>
  			<mu2>25.0</mu2>
      		<kp  value="10000000000.0" />
      		<kd  value="10000000000.0" /-->
    <dampingFactor>10</dampingFactor>
    <minDepth>1</minDepth>
    <material>Gazebo/Grey</material>
  </gazebo>
  <!--<gazebo reference="roller_${name}_rim_${parent}_joint">
    <selfCollide>False</selfCollide>
    <dampingFactor>10</dampingFactor>
    <minDepth>0.001</minDepth>
  </gazebo>-->
  <link name="roller_se_rim_right_link">
    <inertial>
      <mass value="0.1"/>
      <inertia ixx="6.8e-01" ixy="0" ixz="0" iyy="6.8e-01" iyz="0" izz="0.0101"/>
    </inertial>
    <visual>
      <geometry>
        <mesh filename="package://demo_navi/src/meshes/roller.stl"/>
      </geometry>
      <material name="roller_material">
        <color rgba="0.1 0.1 0.1 1"/>
      </material>
    </visual>
    <collision>
      <geometry>
        <mesh filename="package://demo_navi/src/meshes/roller.stl"/>
      </geometry>
    </collision>
  </link>
  <joint name="roller_se_rim_right_joint" type="continuous">
    <parent link="rim_right_link"/>
    <child link="roller_se_rim_right_link"/>
    <axis xyz="0 1 0"/>
    <origin rpy="-1.0472 0 0" xyz="-0.0146 -0.023 -0.0133"/>
    <limit effort="100000000" velocity="10"/>
  </joint>
  <gazebo reference="roller_se_rim_right_link">
    <!--<mu1>50.0</mu1>
  			<mu2>25.0</mu2>
      		<kp  value="10000000000.0" />
      		<kd  value="10000000000.0" /-->
    <dampingFactor>10</dampingFactor>
    <minDepth>1</minDepth>
    <material>Gazebo/Grey</material>
  </gazebo>
  <!--<gazebo reference="roller_${name}_rim_${parent}_joint">
    <selfCollide>False</selfCollide>
    <dampingFactor>10</dampingFactor>
    <minDepth>0.001</minDepth>
  </gazebo>-->
  <transmission name="rim_right_transmission">
    <type>transmission_interface/SimpleTransmission</type>
    <joint name="rim_right_joint">
      <hardwareInterface>hardware_interface/VelocityJointInterface</hardwareInterface>
    </joint>
    <actuator name="rim_right_motor">
      <hardwareInterface>hardware_interface/VelocityJointInterface</hardwareInterface>
      <mechanicalReduction>1</mechanicalReduction>
    </actuator>
  </transmission>
  <gazebo reference="rim_right_link">
    <!--mu1>50.0</mu1>
  				<mu2>25.0</mu2-->
    <!--kp  value="10000000.0" />
      			<selfCollide>False</selfCollide>
      			<kd  value="10000000.0" /-->
    <dampingFactor>10</dampingFactor>
    <minDepth>1</minDepth>
  </gazebo>
  <joint name="sick_joint_R" type="fixed">
    <parent link="base_link"/>
    <child link="sick_R_laser"/>
    <!-- allakse to adress -->
    <origin rpy="-3.1415 0 -1.0472" xyz="0.008 -0.275 0.042"/>
  </joint>
  <link name="sick_R_laser">
    <visual>
      <geometry>
        <mesh filename="package://demo_navi/src/meshes/sick_tim_5xx.stl"/>
      </geometry>
      <material name="blue">
        <color rgba="0 0 1 1"/>
      </material>
    </visual>
    <collision>
      <geometry>
        <mesh filename="package://demo_navi/src/meshes/sick_tim_5xx.stl"/>
      </geometry>
    </collision>
    <!--inertial>
        <mass value="0.001" />
        <origin xyz="0.008 -0.275 0.042" />
        <inertia ixx="0.000001" ixy="0.0" ixz="0.0"
          iyy="0.000001" iyz="0.0" izz="0.000001" />
      </inertial-->
  </link>
  <joint name="sick_joint_L" type="fixed">
    <parent link="base_link"/>
    <child link="sick_L_laser"/>
    <origin rpy="-3.1415 0 1.0472" xyz="0.008 0.275 0.042"/>
  </joint>
  <link name="sick_L_laser">
    <visual>
      <geometry>
        <mesh filename="package://demo_navi/src/meshes/sick_tim_5xx.stl"/>
      </geometry>
      <material name="blue">
        <color rgba="0 0 1 1"/>
      </material>
    </visual>
    <collision>
      <geometry>
        <mesh filename="package://demo_navi/src/meshes/sick_tim_5xx.stl"/>
      </geometry>
    </collision>
    <!--inertial>
        <mass value="0.001" />
        <origin xyz="0 0.27 0.07" />
        <inertia ixx="0.000001" ixy="0.0" ixz="0.0"
          iyy="0.000001" iyz="0.0" izz="0.000001" />
      </inertial-->
  </link>
  <gazebo>
    <plugin filename="libgazebo_ros_control.so" name="gazebo_ros_control">
      <robotNamespace>/demo_DIR</robotNamespace>
    </plugin>
  </gazebo>
  <!--<gazebo reference="base_link">
	<dampingFactor>10</dampingFactor>
	<minDepth>0.001</minDepth>
   </gazebo>-->
  <gazebo>
    <plugin filename="libgazebo_ros_planar_move.so" name="object_controller">
      <commandTopic>/gaz_controller/cmd_vel</commandTopic>
      <leftJoint>left_rim_joint</leftJoint>
      <rightJoint>right_rim_joint</rightJoint>
      <backJoint>back_rim_joint</backJoint>
      <wheelSeparation>0.25</wheelSeparation>
      <wheelDiameter>0.7</wheelDiameter>
      <torque>10</torque>
      <odometryTopic>odom</odometryTopic>
      <odometryFrame>odom</odometryFrame>
      <odometryRate>20.0</odometryRate>
      <robotBaseFrame>base_footprint</robotBaseFrame>
    </plugin>
  </gazebo>
  <gazebo reference="imu_link">
    <gravity>true</gravity>
    <sensor name="imu_sensor" type="imu">
      <always_on>true</always_on>
      <update_rate>100</update_rate>
      <visualize>true</visualize>
      <topic>__default_topic_imu_link__</topic>
      <plugin filename="libgazebo_ros_imu_sensor.so" name="imu_plugin">
        <topicName>imu</topicName>
        <bodyName>imu_link</bodyName>
        <updateRateHZ>10.0</updateRateHZ>
        <gaussianNoise>0.0</gaussianNoise>
        <xyzOffset>0 0 0</xyzOffset>
        <rpyOffset>0 0 0</rpyOffset>
        <frameName>imu_link</frameName>
        <initialOrientationAsReference>false</initialOrientationAsReference>
      </plugin>
      <pose>0 0 0 0 0 0</pose>
    </sensor>
  </gazebo>
  <gazebo reference="sick_L_laser">
    <material value="Gazebo/Blue"/>
    <sensor name="sick_lms_5_laser_gazebo_v0" type="ray">
      <always_on>true</always_on>
      <update_rate>15.0</update_rate>
      <pose>0 0 0 0 0 0</pose>
      <visualize>false</visualize>
      <ray>
        <scan>
          <horizontal>
            <samples>811</samples>
            <resolution>1</resolution>
            <min_angle>-1.0</min_angle>
            <!--90 moires -->
            <max_angle>2.357</max_angle>
            <!--140 moires -->
          </horizontal>
        </scan>
        <range>
          <min>0.15</min>
          <max>4.0</max>
          <resolution>0.01</resolution>
        </range>
      </ray>
      <plugin filename="libgazebo_ros_laser.so" name="gazebo_ros_sick_lms_5_laser_gazebo_v0_controller">
        <gaussianNoise>0.005</gaussianNoise>
        <alwaysOn>true</alwaysOn>
        <updateRate>15.0</updateRate>
        <topicName>scan_L</topicName>
        <frameName>sick_L_laser</frameName>
      </plugin>
    </sensor>
  </gazebo>
  <gazebo reference="sick_R_laser">
    <material value="Gazebo/Blue"/>
    <sensor name="sick_lms_5_laser_gazebo_v01" type="ray">
      <always_on>true</always_on>
      <update_rate>15.0</update_rate>
      <pose>0 0 0 0 0 0</pose>
      <visualize>false</visualize>
      <ray>
        <scan>
          <horizontal>
            <samples>811</samples>
            <resolution>1</resolution>
            <min_angle>-2.357</min_angle>
            <!--140 moires -->
            <max_angle>1.0</max_angle>
            <!--90 moires -->
          </horizontal>
        </scan>
        <range>
          <min>0.15</min>
          <max>4.0</max>
          <resolution>0.01</resolution>
        </range>
      </ray>
      <plugin filename="libgazebo_ros_laser.so" name="gazebo_ros_sick_lms_5_laser_gazebo_v01_controller">
        <gaussianNoise>0.005</gaussianNoise>
        <alwaysOn>true</alwaysOn>
        <updateRate>15.0</updateRate>
        <topicName>scan_R</topicName>
        <frameName>sick_R_laser</frameName>
      </plugin>
    </sensor>
  </gazebo>
  <gazebo>
    <plugin filename="libgazebo_grasp_fix.so" name="gazebo_grasp_fix">
      <arm>
        <arm_name>widowxl</arm_name>
        <palm_link>wrist_2_link</palm_link>
        <gripper_link>gripper_1_link</gripper_link>
        <gripper_link>gripper_2_link</gripper_link>
      </arm>
      <forces_angle_tolerance>100</forces_angle_tolerance>
      <update_rate>4</update_rate>
      <grip_count_threshold>4</grip_count_threshold>
      <max_grip_count>8</max_grip_count>
      <release_tolerance>0.007</release_tolerance>
      <disable_collisions_on_attach>false</disable_collisions_on_attach>
      <contact_topic>__default_topic__</contact_topic>
    </plugin>
  </gazebo>
  <gazebo reference="base_link">
    <material>Gazebo/Crimson</material>
  </gazebo>
  <gazebo reference="rim_left_link">
    <material>Gazebo/Black</material>
  </gazebo>
  <gazebo reference="rim_back_link">
    <material>Gazebo/Black</material>
  </gazebo>
  <gazebo reference="rim_right_link">
    <material>Gazebo/Black</material>
  </gazebo>
</robot>
