<?xml version="1.0"?>
<robot
	xmlns:xacro="http://www.ros.org/wiki/xacro"
  name="demo_DIR"
>

	<xacro:include filename="$(find demo_navi)/src/urdf/xacro/rim.urdf.xacro"/>
  <xacro:include filename="$(find demo_navi)/src/urdf/xacro/common_materials.xacro" />

	<link name="base_footprint"/>

	<link name="base_link">

	<inertial>
		<origin xyz="-0.147 0 0"
			rpy="0 0 0" />
		<mass value="5"/>
		<inertia
			ixx="0.15"
			ixy="0"
			ixz="0"
			iyy="0.104167"
			iyz="0"
			izz="0.254167"
		/>

	</inertial>
	<visual>
		<origin xyz="0 0 0"
			rpy="0 0 0" />

		<geometry>

			<mesh filename="package://demo_navi/src/meshes/base_link.stl"/>

		</geometry>
		<material name="base_material">

			<color rgba="0.098039 0.098039 0.098039 1"/>

		</material>

	</visual>
	<collision>
		<origin xyz="0 0 0"
			rpy="0 0 0" />

		<geometry>

			<mesh filename="package://demo_navi/src/meshes/base_link.stl"/>

		</geometry>

	</collision>

	</link>
	<joint
		name="base_joint"
		type="fixed"
	>

		<parent link="base_footprint" />
		<child link="base_link" />
		<origin
			xyz="0 0 0"
		/>

	</joint>
	<xacro:rim_macro
		name="left"
		color="0.3 0 0"
		xyz="-0.0267 0.214 0.04"
		rpy="0 0 -2.0944"
	/>
	<xacro:rim_macro
		name="back"
		color="0.3 0 0"
		xyz="-0.397 0 0.04"
		rpy="0 0 0"
	/>
	<xacro:rim_macro
		name="right"
		color="0.3 0 0"
		xyz="-0.0267 -0.214 0.04"
		rpy="0 0 2.0944"
	/>


    <joint name="sick_joint_R" type="fixed">
      <parent link="base_link" />
      <child link="sick_R_laser" /><!-- allakse to adress -->
      <origin rpy="-3.1415 0 -1.0472" xyz="0.008 -0.275 0.042"/>
    </joint>

    <link name="sick_R_laser">
      <visual>
        <geometry>
          <mesh filename="package://demo_navi/src/meshes/sick_tim_5xx.stl"/>
        </geometry>
        <material name="blue" >
          <color rgba="0 0 1 1" />
        </material>
      </visual>
      <collision>
        <geometry>
          <mesh filename="package://demo_navi/src/meshes/sick_tim_5xx.stl"/>
        </geometry>
      </collision>
      <inertial>
        <mass value="0.001" />
        <origin xyz="0.008 -0.275 0.042" />
        <inertia ixx="0.000001" ixy="0.0" ixz="0.0"
          iyy="0.000001" iyz="0.0" izz="0.000001" />
      </inertial>
    </link>

    <joint name="sick_joint_L" type="fixed">
      <parent link="base_link" />
      <child link="sick_L_laser" />
      <origin rpy="-3.1415 0 1.0472" xyz="0.008 0.275 0.042"/>
    </joint>

    <link name="sick_L_laser">
      <visual>
        <geometry>
          <mesh filename="package://demo_navi/src/meshes/sick_tim_5xx.stl"/>
        </geometry>
        <material name="blue" >
          <color rgba="0 0 1 1" />
        </material>
      </visual>
      <collision>
        <geometry>
          <mesh filename="package://demo_navi/src/meshes/sick_tim_5xx.stl"/>
        </geometry>
      </collision>
      <inertial>
        <mass value="0.001" />
        <origin xyz="0 0.27 0.07" />
        <inertia ixx="0.000001" ixy="0.0" ixz="0.0"
          iyy="0.000001" iyz="0.0" izz="0.000001" />
      </inertial>
    </link>

    <!--WIDOWXL ARM LINKS & JOINTS-->
          <link name="shoulder_link">
         <visual>
            <geometry>
               <mesh filename="package://demo_navi/src/meshes/arm/shoulder_link.stl" />
            </geometry>
            <xacro:material_black />
         </visual>
         <collision>
            <geometry>
               <mesh filename="package://demo_navi/src/meshes/arm/shoulder_link.stl"/>
            </geometry>
         </collision>
         <inertial>
            <mass value="0.1" />
            <inertia ixx="0.1" ixy="0.0" ixz="0.0" iyy="0.1" iyz="0.0" izz="0.1" />
         </inertial>
      </link>
      <link name="biceps_link">
         <visual>
            <geometry>
               <mesh filename="package://demo_navi/src/meshes/arm/biceps_link.stl" />
            </geometry>
            <xacro:material_black />
         </visual>
         <collision>
            <geometry>
               <mesh filename="package://demo_navi/src/meshes/arm/biceps_link.stl" />
            </geometry>
         </collision>
         <inertial>
            <mass value="0.1" />
            <inertia ixx="0.1" ixy="0.0" ixz="0.0" iyy="0.1" iyz="0.0" izz="0.1" />
         </inertial>
      </link>
      <link name="forearm_link">
         <visual>
            <geometry>
               <mesh filename="package://demo_navi/src/meshes/arm/forearm_link.stl"/>
            </geometry>
           <xacro:material_black />
         </visual>
         <collision>
            <geometry>
               <mesh filename="package://demo_navi/src/meshes/arm/forearm_link.stl"/>
            </geometry>
         </collision>
         <inertial>
            <mass value="0.1" />
            <inertia ixx="1.0" ixy="0.0" ixz="0.0" iyy="1.0" iyz="0.0" izz="1.0"/>
         </inertial>
      </link>
      <link name="wrist_1_link">
         <visual>
            <geometry>
               <mesh filename="package://demo_navi/src/meshes/arm/wrist_1_link.stl"/>
            </geometry>
            <xacro:material_black />
         </visual>
         <collision>
            <geometry>
               <mesh filename="package://demo_navi/src/meshes/arm/wrist_1_link.stl"/>
            </geometry>
         </collision>
         <inertial>
            <mass value="0.1" />
            <inertia ixx="0.1" ixy="0.0" ixz="0.0" iyy="0.1" iyz="0.0" izz="0.1" />
         </inertial>
      </link>
      <link name="wrist_2_link">
         <visual>
            <geometry>
               <mesh filename="package://demo_navi/src/meshes/arm/wrist_2_link.stl"/>
            </geometry>
            <xacro:material_black />
         </visual>
         <collision>
            <geometry>
               <mesh filename="package://demo_navi/src/meshes/arm/wrist_2_link.stl"/>
            </geometry>
         </collision>
         <inertial>
            <mass value="0.1" />
            <inertia ixx="0.1" ixy="0.0" ixz="0.0" iyy="0.1" iyz="0.0" izz="0.1" />
         </inertial>
      </link>
      <link name="gripper_rail_link">
         <visual>
            <geometry>
               <mesh filename="package://demo_navi/src/meshes/arm/gripper_rail_link.stl"/>
            </geometry>
            <xacro:material_black />
         </visual>
         <collision>
            <geometry>
               <mesh filename="package://demo_navi/src/meshes/arm/gripper_rail_link.stl"/>
            </geometry>
         </collision>
         <inertial>
            <mass value="0.1" />
            <inertia ixx="0.1" ixy="0.0" ixz="0.0" iyy="0.1" iyz="0.0" izz="0.1" />
         </inertial>
      </link>
      <link name="gripper_1_link">
         <visual>
            <geometry>
               <mesh filename="package://demo_navi/src/meshes/arm/gripper_hand_fixed_link.stl"/>
            </geometry>
            <xacro:material_black />
         </visual>
         <collision>
            <geometry>
               <mesh filename="package://demo_navi/src/meshes/arm/gripper_hand_fixed_link.stl"/>
            </geometry>
         </collision>
         <inertial>
            <mass value="0.1" />
            <inertia ixx="0.1" ixy="0.0" ixz="0.0" iyy="0.1" iyz="0.0" izz="0.1" />
         </inertial>
      </link>
      <link name="gripper_2_link">
         <visual>
            <geometry>
               <mesh filename="package://demo_navi/src/meshes/arm/gripper_hand_fixed_link.stl"/>
            </geometry>
            <xacro:material_black />
         </visual>
         <collision>
            <geometry>
               <mesh filename="package://demo_navi/src/meshes/arm/gripper_hand_fixed_link.stl"/>
            </geometry>
         </collision>
         <inertial>
            <mass value="0.1" />
            <inertia ixx="0.1" ixy="0.0" ixz="0.0" iyy="0.1" iyz="0.0" izz="0.1" />
         </inertial>
      </link>
      <!-- joints -->
      <joint name="joint_1" type="revolute">
         <origin xyz="0.0033 -0.0017 0.15" rpy="0 0 0" />
         <parent link="base_link" />
         <child link="shoulder_link" />
         <axis xyz="0 0 1" />
         <limit lower="-2.617" upper="2.617" effort="0" velocity="0.785" />
      </joint>
      <joint name="joint_2" type="revolute">
         <!--origin xyz="0.04825 0 0.14203" rpy="0 0 0" /-->
         <origin xyz="0.051 0.003 0.142" rpy="0 0 0" />
         <parent link="shoulder_link" />
         <child link="biceps_link" />
         <axis xyz="0 1 0" />
         <limit lower="-1.571" upper="1.571" effort="0" velocity="1.571" />
      </joint>
      <joint name="joint_3" type="revolute">
         <origin xyz="-0.002 -0.003 0.14057" rpy="0 0 0" />
         <parent link="biceps_link" />
         <child link="forearm_link" />
         <axis xyz="0 1 0" />
         <limit lower="-1.571" upper="1.571" effort="0" velocity="1.571" />
      </joint>
      <joint name="joint_4" type="revolute">
         <origin xyz="0.0027 -0.002 0.008" rpy="0 0 0" />
         <parent link="forearm_link" />
         <child link="wrist_1_link" />
         <axis xyz="0 1 0" />
         <limit lower="-1.745" upper="1.745" effort="0" velocity="1.571" />
      </joint>
      <joint name="joint_5" type="revolute">
         <origin xyz="0 0 0.08" rpy="0 0 0" />
         <parent link="wrist_1_link" />
         <child link="wrist_2_link" />
         <axis xyz="0 0 1" />
         <limit lower="-2.617" upper="2.617" effort="0" velocity="1.571" />
      </joint>
      <joint name="joint_6" type="revolute">
         <origin xyz = "0 0 0.04" rpy="0 0 0" />
         <parent link="wrist_2_link" />
         <child link="gripper_rail_link" />
         <axis xyz="0 0 1" />
         <limit lower="-0.31" upper="0.1" effort="0" velocity="0.5" />
      </joint>
      <joint name="gripper_prismatic_joint_1" type="prismatic">
         <origin xyz="0 0 0" rpy="0 0 0" />
         <parent link="gripper_rail_link" />
         <child link="gripper_1_link" />
         <axis xyz="0 1 0" />
         <limit lower="0" upper="0.027" effort="0" velocity="0.5" />
      </joint>
      <joint name="gripper_prismatic_joint_2" type="prismatic">
         <origin xyz="0 0 0" rpy="0 0 3.1415" />
         <parent link="gripper_rail_link" />
         <child link="gripper_2_link" />
         <mimic joint="gripper_prismatic_joint_1" />
         <axis xyz="0 -1 0" />
         <limit lower="0" upper="0.027" effort="0" velocity="0.5" />
      </joint>


  <transmission name="tran1">
    <type>transmission_interface/SimpleTransmission</type>
    <joint name="joint_1">
          <hardwareInterface>hardware_interface/EffortJointInterface</hardwareInterface>
    </joint>
    <actuator name="motor1">
      <hardwareInterface>hardware_interface/EffortJointInterface</hardwareInterface>
      <mechanicalReduction>1</mechanicalReduction>
    </actuator>
  </transmission>

 <transmission name="tran2">
    <type>transmission_interface/SimpleTransmission</type>
    <joint name="joint_2">
          <hardwareInterface>hardware_interface/EffortJointInterface</hardwareInterface>
    </joint>
    <actuator name="motor2">
      <hardwareInterface>hardware_interface/EffortJointInterface</hardwareInterface>
      <mechanicalReduction>1</mechanicalReduction>
    </actuator>
  </transmission>

 <transmission name="tran3">
    <type>transmission_interface/SimpleTransmission</type>
    <joint name="joint_3">
          <hardwareInterface>hardware_interface/EffortJointInterface</hardwareInterface>
    </joint>
    <actuator name="motor3">
      <hardwareInterface>hardware_interface/EffortJointInterface</hardwareInterface>
      <mechanicalReduction>1</mechanicalReduction>
    </actuator>
  </transmission>

 <transmission name="tran4">
    <type>transmission_interface/SimpleTransmission</type>
    <joint name="joint_4">
          <hardwareInterface>hardware_interface/EffortJointInterface</hardwareInterface>
    </joint>
    <actuator name="motor4">
      <hardwareInterface>hardware_interface/EffortJointInterface</hardwareInterface>
      <mechanicalReduction>1</mechanicalReduction>
    </actuator>
  </transmission>

 <transmission name="tran5">
    <type>transmission_interface/SimpleTransmission</type>
    <joint name="joint_5">
          <hardwareInterface>hardware_interface/EffortJointInterface</hardwareInterface>
    </joint>
    <actuator name="motor5">
      <hardwareInterface>hardware_interface/EffortJointInterface</hardwareInterface>
      <mechanicalReduction>1</mechanicalReduction>
    </actuator>
  </transmission>

   <transmission name="tran6">
    <type>transmission_interface/SimpleTransmission</type>
    <joint name="joint_6">
          <hardwareInterface>hardware_interface/EffortJointInterface</hardwareInterface>
    </joint>
    <actuator name="motor6">
      <hardwareInterface>hardware_interface/EffortJointInterface</hardwareInterface>
      <mechanicalReduction>1</mechanicalReduction>
    </actuator>
  </transmission>

  <transmission name="tran7">
    <type>transmission_interface/SimpleTransmission</type>
    <joint name="gripper_prismatic_joint_1">
          <hardwareInterface>hardware_interface/EffortJointInterface</hardwareInterface>
    </joint>
    <actuator name="motor7">
      <hardwareInterface>hardware_interface/EffortJointInterface</hardwareInterface>
      <mechanicalReduction>1</mechanicalReduction>
    </actuator>
  </transmission>

  <transmission name="tran8">
    <type>transmission_interface/SimpleTransmission</type>
    <joint name="gripper_prismatic_joint_2">
          <hardwareInterface>hardware_interface/EffortJointInterface</hardwareInterface>
    </joint>
    <actuator name="motor8">
      <hardwareInterface>hardware_interface/EffortJointInterface</hardwareInterface>
      <mechanicalReduction>1</mechanicalReduction>
    </actuator>
  </transmission>


	<gazebo>

		<plugin name="gazebo_ros_control" filename="libgazebo_ros_control.so">

			<robotNamespace>/demo_DIR</robotNamespace>

		</plugin>

	</gazebo>

   <!--<gazebo reference="base_link">
	<dampingFactor>10</dampingFactor>
	<minDepth>0.001</minDepth>
   </gazebo>-->

    <gazebo>
     <plugin name="object_controller" filename="libgazebo_ros_planar_move.so">
       <commandTopic>/gaz_controller/cmd_vel</commandTopic>
       <leftJoint>left_rim_joint</leftJoint>
       <rightJoint>right_rim_joint</rightJoint>
       <backJoint>back_rim_joint</backJoint>
       <wheelSeparation>0.25</wheelSeparation>
       <wheelDiameter>0.7</wheelDiameter>
       <torque>10</torque>
       <odometryTopic>odom</odometryTopic>
       <odometryFrame>odom</odometryFrame>
       <odometryRate>20.0</odometryRate>
       <robotBaseFrame>base_footprint</robotBaseFrame>
     </plugin>
   </gazebo>


    <gazebo reference="sick_L_laser">
    <material value="Gazebo/Blue" />
    <sensor type="ray" name="sick_lms_5_laser_gazebo_v0">
      <always_on>true</always_on>
      <update_rate>15.0</update_rate>
      <pose>0 0 0 0 0 0</pose>
      <visualize>false</visualize>
      <ray>
        <scan>
          <horizontal>
            <samples>811</samples>
            <resolution>1</resolution>
            <min_angle>-1.0</min_angle> <!--90 moires -->
            <max_angle>2.357</max_angle> <!--140 moires -->
          </horizontal>
        </scan>
        <range>
          <min>0.15</min>
          <max>4.0</max>
          <resolution>0.01</resolution>
        </range>
      </ray>
      <plugin name="gazebo_ros_sick_lms_5_laser_gazebo_v0_controller" filename="libgazebo_ros_laser.so">
        <gaussianNoise>0.005</gaussianNoise>
        <alwaysOn>true</alwaysOn>
        <updateRate>15.0</updateRate>
        <topicName>scan_L</topicName>     
        <frameName>sick_L_laser</frameName>
      </plugin>
    </sensor>
   </gazebo>

  <gazebo reference="sick_R_laser">
    <material value="Gazebo/Blue" />
    <sensor type="ray" name="sick_lms_5_laser_gazebo_v01">
      <always_on>true</always_on>
      <update_rate>15.0</update_rate>
      <pose>0 0 0 0 0 0</pose>
      <visualize>false</visualize>
      <ray>
        <scan>
          <horizontal>
            <samples>811</samples>
            <resolution>1</resolution>
            <min_angle>-2.357</min_angle> <!--140 moires -->
            <max_angle>1.0</max_angle> <!--90 moires -->
          </horizontal>
        </scan>
        <range>
          <min>0.15</min>
          <max>4.0</max>
          <resolution>0.01</resolution>
        </range>
      </ray>
      <plugin name="gazebo_ros_sick_lms_5_laser_gazebo_v01_controller" filename="libgazebo_ros_laser.so">
        <gaussianNoise>0.005</gaussianNoise>
        <alwaysOn>true</alwaysOn>
        <updateRate>15.0</updateRate>
        <topicName>scan_R</topicName> 
        <frameName>sick_R_laser</frameName>
      </plugin>
    </sensor>
  </gazebo>


	<gazebo reference="base_link">
    		<material>Gazebo/Crimson</material>
  	</gazebo>

	<gazebo reference="rim_left_link">
    		<material>Gazebo/Black</material>
  	</gazebo>

	<gazebo reference="rim_back_link">
    		<material>Gazebo/Black</material>
  	</gazebo>

	<gazebo reference="rim_right_link">
    		<material>Gazebo/Black</material>
  	</gazebo>
	

</robot>
