<?xml version="1.0" encoding="utf-8"?>
<!-- =================================================================================== -->
<!-- |    This document was autogenerated by xacro from main.urdf.xacro                | -->
<!-- |    EDITING THIS FILE BY HAND IS NOT RECOMMENDED                                 | -->
<!-- =================================================================================== -->
<robot name="demo_DIR">
  <link name="base_footprint"/>
  <link name="base_link">
    <inertial>
      <origin rpy="0 0 0" xyz="-0.147 0 0"/>
      <mass value="5"/>
      <inertia ixx="0.15" ixy="0" ixz="0" iyy="0.104167" iyz="0" izz="0.254167"/>
    </inertial>
    <visual>
      <origin rpy="0 0 0" xyz="0 0 0"/>
      <geometry>
        <mesh filename="package://demo_navi/src/meshes/base_link.stl"/>
      </geometry>
      <material name="base_material">
        <color rgba="0.098039 0.098039 0.098039 1"/>
      </material>
    </visual>
    <collision>
      <origin rpy="0 0 0" xyz="0 0 0"/>
      <geometry>
        <mesh filename="package://demo_navi/src/meshes/base_link.stl"/>
      </geometry>
    </collision>
  </link>
  <joint name="base_joint" type="fixed">
    <parent link="base_footprint"/>
    <child link="base_link"/>
    <origin xyz="0 0 0"/>
  </joint>
  <link name="rim_left_link">
    <inertial>
      <origin xyz="0 0 0"/>
      <mass value="1"/>
      <inertia ixx="0.0007" ixy="0" ixz="0" iyy="0.0007" iyz="0" izz="0.0008"/>
    </inertial>
    <visual>
      <geometry>
        <mesh filename="package://demo_navi/src/meshes/rim.stl"/>
      </geometry>
      <material name="rim_left_material">
        <color rgba="0.3 0 0 1"/>
      </material>
    </visual>
    <collision>
      <geometry>
        <mesh filename="package://demo_navi/src/meshes/rim.stl"/>
      </geometry>
    </collision>
  </link>
  <joint name="rim_left_joint" type="continuous">
    <parent link="base_link"/>
    <child link="rim_left_link"/>
    <axis xyz="1 0 0"/>
    <origin rpy="0 0 -2.0944" xyz="-0.0267 0.214 0.04"/>
    <!--<limit effort="100000" velocity="100000"/>
			<joint_properties friction="1.0"/>-->
  </joint>
  <link name="roller_s_rim_left_link">
    <inertial>
      <mass value="0.1"/>
      <inertia ixx="6.8e-05" ixy="0" ixz="0" iyy="6.8e-05" iyz="0" izz="0.000101"/>
    </inertial>
    <visual>
      <geometry>
        <mesh filename="package://demo_navi/src/meshes/roller.stl"/>
      </geometry>
      <material name="roller_material">
        <color rgba="0.1 0.1 0.1 1"/>
      </material>
    </visual>
    <collision>
      <geometry>
        <mesh filename="package://demo_navi/src/meshes/roller.stl"/>
      </geometry>
    </collision>
  </link>
  <joint name="roller_s_rim_left_joint" type="continuous">
    <parent link="rim_left_link"/>
    <child link="roller_s_rim_left_link"/>
    <axis xyz="0 1 0"/>
    <origin rpy="0 0 0" xyz="0.0153 0 -0.0266"/>
  </joint>
  <gazebo reference="roller_s_rim_left_link">
    <!--<mu1>5000.0</mu1>
  				<mu2>2500.0</mu2>
      			<kp  value="10000000.0" />
      			<maxContacts  value="10" />
      			<kd  value="1.0" />
      			<fdir1 value="1 0 0"/>-->
    <material>Gazebo/Grey</material>
  </gazebo>
  <!--<gazebo reference="roller_${name}_rim_${parent}_joint">
    <dampingFactor>10</dampingFactor>
    <minDepth>0.001</minDepth>
  </gazebo>-->
  <link name="roller_nw_rim_left_link">
    <inertial>
      <mass value="0.1"/>
      <inertia ixx="6.8e-05" ixy="0" ixz="0" iyy="6.8e-05" iyz="0" izz="0.000101"/>
    </inertial>
    <visual>
      <geometry>
        <mesh filename="package://demo_navi/src/meshes/roller.stl"/>
      </geometry>
      <material name="roller_material">
        <color rgba="0.1 0.1 0.1 1"/>
      </material>
    </visual>
    <collision>
      <geometry>
        <mesh filename="package://demo_navi/src/meshes/roller.stl"/>
      </geometry>
    </collision>
  </link>
  <joint name="roller_nw_rim_left_joint" type="continuous">
    <parent link="rim_left_link"/>
    <child link="roller_nw_rim_left_link"/>
    <axis xyz="0 1 0"/>
    <origin rpy="1.0472 0 0" xyz="0.015 -0.0231 0.0131"/>
  </joint>
  <gazebo reference="roller_nw_rim_left_link">
    <!--<mu1>5000.0</mu1>
  				<mu2>2500.0</mu2>
      			<kp  value="10000000.0" />
      			<maxContacts  value="10" />
      			<kd  value="1.0" />
      			<fdir1 value="1 0 0"/>-->
    <material>Gazebo/Grey</material>
  </gazebo>
  <!--<gazebo reference="roller_${name}_rim_${parent}_joint">
    <dampingFactor>10</dampingFactor>
    <minDepth>0.001</minDepth>
  </gazebo>-->
  <link name="roller_ne_rim_left_link">
    <inertial>
      <mass value="0.1"/>
      <inertia ixx="6.8e-05" ixy="0" ixz="0" iyy="6.8e-05" iyz="0" izz="0.000101"/>
    </inertial>
    <visual>
      <geometry>
        <mesh filename="package://demo_navi/src/meshes/roller.stl"/>
      </geometry>
      <material name="roller_material">
        <color rgba="0.1 0.1 0.1 1"/>
      </material>
    </visual>
    <collision>
      <geometry>
        <mesh filename="package://demo_navi/src/meshes/roller.stl"/>
      </geometry>
    </collision>
  </link>
  <joint name="roller_ne_rim_left_joint" type="continuous">
    <parent link="rim_left_link"/>
    <child link="roller_ne_rim_left_link"/>
    <axis xyz="0 1 0"/>
    <origin rpy="-1.0472 0 0" xyz="0.015 0.0231 0.0135"/>
  </joint>
  <gazebo reference="roller_ne_rim_left_link">
    <!--<mu1>5000.0</mu1>
  				<mu2>2500.0</mu2>
      			<kp  value="10000000.0" />
      			<maxContacts  value="10" />
      			<kd  value="1.0" />
      			<fdir1 value="1 0 0"/>-->
    <material>Gazebo/Grey</material>
  </gazebo>
  <!--<gazebo reference="roller_${name}_rim_${parent}_joint">
    <dampingFactor>10</dampingFactor>
    <minDepth>0.001</minDepth>
  </gazebo>-->
  <link name="roller_sw_rim_left_link">
    <inertial>
      <mass value="0.1"/>
      <inertia ixx="6.8e-05" ixy="0" ixz="0" iyy="6.8e-05" iyz="0" izz="0.000101"/>
    </inertial>
    <visual>
      <geometry>
        <mesh filename="package://demo_navi/src/meshes/roller.stl"/>
      </geometry>
      <material name="roller_material">
        <color rgba="0.1 0.1 0.1 1"/>
      </material>
    </visual>
    <collision>
      <geometry>
        <mesh filename="package://demo_navi/src/meshes/roller.stl"/>
      </geometry>
    </collision>
  </link>
  <joint name="roller_sw_rim_left_joint" type="continuous">
    <parent link="rim_left_link"/>
    <child link="roller_sw_rim_left_link"/>
    <axis xyz="0 1 0"/>
    <origin rpy="1.0472 0 0" xyz="-0.0146 0.023 -0.0133"/>
  </joint>
  <gazebo reference="roller_sw_rim_left_link">
    <!--<mu1>5000.0</mu1>
  				<mu2>2500.0</mu2>
      			<kp  value="10000000.0" />
      			<maxContacts  value="10" />
      			<kd  value="1.0" />
      			<fdir1 value="1 0 0"/>-->
    <material>Gazebo/Grey</material>
  </gazebo>
  <!--<gazebo reference="roller_${name}_rim_${parent}_joint">
    <dampingFactor>10</dampingFactor>
    <minDepth>0.001</minDepth>
  </gazebo>-->
  <link name="roller_n_rim_left_link">
    <inertial>
      <mass value="0.1"/>
      <inertia ixx="6.8e-05" ixy="0" ixz="0" iyy="6.8e-05" iyz="0" izz="0.000101"/>
    </inertial>
    <visual>
      <geometry>
        <mesh filename="package://demo_navi/src/meshes/roller.stl"/>
      </geometry>
      <material name="roller_material">
        <color rgba="0.1 0.1 0.1 1"/>
      </material>
    </visual>
    <collision>
      <geometry>
        <mesh filename="package://demo_navi/src/meshes/roller.stl"/>
      </geometry>
    </collision>
  </link>
  <joint name="roller_n_rim_left_joint" type="continuous">
    <parent link="rim_left_link"/>
    <child link="roller_n_rim_left_link"/>
    <axis xyz="0 1 0"/>
    <origin rpy="0 0 0" xyz="-0.0146 0 0.0268"/>
  </joint>
  <gazebo reference="roller_n_rim_left_link">
    <!--<mu1>5000.0</mu1>
  				<mu2>2500.0</mu2>
      			<kp  value="10000000.0" />
      			<maxContacts  value="10" />
      			<kd  value="1.0" />
      			<fdir1 value="1 0 0"/>-->
    <material>Gazebo/Grey</material>
  </gazebo>
  <!--<gazebo reference="roller_${name}_rim_${parent}_joint">
    <dampingFactor>10</dampingFactor>
    <minDepth>0.001</minDepth>
  </gazebo>-->
  <link name="roller_se_rim_left_link">
    <inertial>
      <mass value="0.1"/>
      <inertia ixx="6.8e-05" ixy="0" ixz="0" iyy="6.8e-05" iyz="0" izz="0.000101"/>
    </inertial>
    <visual>
      <geometry>
        <mesh filename="package://demo_navi/src/meshes/roller.stl"/>
      </geometry>
      <material name="roller_material">
        <color rgba="0.1 0.1 0.1 1"/>
      </material>
    </visual>
    <collision>
      <geometry>
        <mesh filename="package://demo_navi/src/meshes/roller.stl"/>
      </geometry>
    </collision>
  </link>
  <joint name="roller_se_rim_left_joint" type="continuous">
    <parent link="rim_left_link"/>
    <child link="roller_se_rim_left_link"/>
    <axis xyz="0 1 0"/>
    <origin rpy="-1.0472 0 0" xyz="-0.0146 -0.023 -0.0133"/>
  </joint>
  <gazebo reference="roller_se_rim_left_link">
    <!--<mu1>5000.0</mu1>
  				<mu2>2500.0</mu2>
      			<kp  value="10000000.0" />
      			<maxContacts  value="10" />
      			<kd  value="1.0" />
      			<fdir1 value="1 0 0"/>-->
    <material>Gazebo/Grey</material>
  </gazebo>
  <!--<gazebo reference="roller_${name}_rim_${parent}_joint">
    <dampingFactor>10</dampingFactor>
    <minDepth>0.001</minDepth>
  </gazebo>-->
  <transmission name="rim_left_transmission">
    <type>transmission_interface/SimpleTransmission</type>
    <joint name="rim_left_joint">
      <hardwareInterface>hardware_interface/VelocityJointInterface</hardwareInterface>
    </joint>
    <actuator name="rim_left_motor">
      <hardwareInterface>hardware_interface/VelocityJointInterface</hardwareInterface>
      <mechanicalReduction>1</mechanicalReduction>
    </actuator>
  </transmission>
  <!--<gazebo reference = "rim_${name}_link">
  				<mu1>5000.0</mu1>
  				<mu2>2500.0</mu2>
      			<kp  value="10000000.0" />
      			<maxContacts  value="10" />
      			<kd  value="1.0" />
      			<fdir1 value="1 0 0"/>
		</gazebo>-->
  <!--<gazebo reference = "rim_${name}_joint">
			<dampingFactor>10</dampingFactor>
			<minDepth>0.001</minDepth>
		</gazebo>-->
  <link name="rim_back_link">
    <inertial>
      <origin xyz="0 0 0"/>
      <mass value="1"/>
      <inertia ixx="0.0007" ixy="0" ixz="0" iyy="0.0007" iyz="0" izz="0.0008"/>
    </inertial>
    <visual>
      <geometry>
        <mesh filename="package://demo_navi/src/meshes/rim.stl"/>
      </geometry>
      <material name="rim_back_material">
        <color rgba="0.3 0 0 1"/>
      </material>
    </visual>
    <collision>
      <geometry>
        <mesh filename="package://demo_navi/src/meshes/rim.stl"/>
      </geometry>
    </collision>
  </link>
  <joint name="rim_back_joint" type="continuous">
    <parent link="base_link"/>
    <child link="rim_back_link"/>
    <axis xyz="1 0 0"/>
    <origin rpy="0 0 0" xyz="-0.397 0 0.04"/>
    <!--<limit effort="100000" velocity="100000"/>
			<joint_properties friction="1.0"/>-->
  </joint>
  <link name="roller_s_rim_back_link">
    <inertial>
      <mass value="0.1"/>
      <inertia ixx="6.8e-05" ixy="0" ixz="0" iyy="6.8e-05" iyz="0" izz="0.000101"/>
    </inertial>
    <visual>
      <geometry>
        <mesh filename="package://demo_navi/src/meshes/roller.stl"/>
      </geometry>
      <material name="roller_material">
        <color rgba="0.1 0.1 0.1 1"/>
      </material>
    </visual>
    <collision>
      <geometry>
        <mesh filename="package://demo_navi/src/meshes/roller.stl"/>
      </geometry>
    </collision>
  </link>
  <joint name="roller_s_rim_back_joint" type="continuous">
    <parent link="rim_back_link"/>
    <child link="roller_s_rim_back_link"/>
    <axis xyz="0 1 0"/>
    <origin rpy="0 0 0" xyz="0.0153 0 -0.0266"/>
  </joint>
  <gazebo reference="roller_s_rim_back_link">
    <!--<mu1>5000.0</mu1>
  				<mu2>2500.0</mu2>
      			<kp  value="10000000.0" />
      			<maxContacts  value="10" />
      			<kd  value="1.0" />
      			<fdir1 value="1 0 0"/>-->
    <material>Gazebo/Grey</material>
  </gazebo>
  <!--<gazebo reference="roller_${name}_rim_${parent}_joint">
    <dampingFactor>10</dampingFactor>
    <minDepth>0.001</minDepth>
  </gazebo>-->
  <link name="roller_nw_rim_back_link">
    <inertial>
      <mass value="0.1"/>
      <inertia ixx="6.8e-05" ixy="0" ixz="0" iyy="6.8e-05" iyz="0" izz="0.000101"/>
    </inertial>
    <visual>
      <geometry>
        <mesh filename="package://demo_navi/src/meshes/roller.stl"/>
      </geometry>
      <material name="roller_material">
        <color rgba="0.1 0.1 0.1 1"/>
      </material>
    </visual>
    <collision>
      <geometry>
        <mesh filename="package://demo_navi/src/meshes/roller.stl"/>
      </geometry>
    </collision>
  </link>
  <joint name="roller_nw_rim_back_joint" type="continuous">
    <parent link="rim_back_link"/>
    <child link="roller_nw_rim_back_link"/>
    <axis xyz="0 1 0"/>
    <origin rpy="1.0472 0 0" xyz="0.015 -0.0231 0.0131"/>
  </joint>
  <gazebo reference="roller_nw_rim_back_link">
    <!--<mu1>5000.0</mu1>
  				<mu2>2500.0</mu2>
      			<kp  value="10000000.0" />
      			<maxContacts  value="10" />
      			<kd  value="1.0" />
      			<fdir1 value="1 0 0"/>-->
    <material>Gazebo/Grey</material>
  </gazebo>
  <!--<gazebo reference="roller_${name}_rim_${parent}_joint">
    <dampingFactor>10</dampingFactor>
    <minDepth>0.001</minDepth>
  </gazebo>-->
  <link name="roller_ne_rim_back_link">
    <inertial>
      <mass value="0.1"/>
      <inertia ixx="6.8e-05" ixy="0" ixz="0" iyy="6.8e-05" iyz="0" izz="0.000101"/>
    </inertial>
    <visual>
      <geometry>
        <mesh filename="package://demo_navi/src/meshes/roller.stl"/>
      </geometry>
      <material name="roller_material">
        <color rgba="0.1 0.1 0.1 1"/>
      </material>
    </visual>
    <collision>
      <geometry>
        <mesh filename="package://demo_navi/src/meshes/roller.stl"/>
      </geometry>
    </collision>
  </link>
  <joint name="roller_ne_rim_back_joint" type="continuous">
    <parent link="rim_back_link"/>
    <child link="roller_ne_rim_back_link"/>
    <axis xyz="0 1 0"/>
    <origin rpy="-1.0472 0 0" xyz="0.015 0.0231 0.0135"/>
  </joint>
  <gazebo reference="roller_ne_rim_back_link">
    <!--<mu1>5000.0</mu1>
  				<mu2>2500.0</mu2>
      			<kp  value="10000000.0" />
      			<maxContacts  value="10" />
      			<kd  value="1.0" />
      			<fdir1 value="1 0 0"/>-->
    <material>Gazebo/Grey</material>
  </gazebo>
  <!--<gazebo reference="roller_${name}_rim_${parent}_joint">
    <dampingFactor>10</dampingFactor>
    <minDepth>0.001</minDepth>
  </gazebo>-->
  <link name="roller_sw_rim_back_link">
    <inertial>
      <mass value="0.1"/>
      <inertia ixx="6.8e-05" ixy="0" ixz="0" iyy="6.8e-05" iyz="0" izz="0.000101"/>
    </inertial>
    <visual>
      <geometry>
        <mesh filename="package://demo_navi/src/meshes/roller.stl"/>
      </geometry>
      <material name="roller_material">
        <color rgba="0.1 0.1 0.1 1"/>
      </material>
    </visual>
    <collision>
      <geometry>
        <mesh filename="package://demo_navi/src/meshes/roller.stl"/>
      </geometry>
    </collision>
  </link>
  <joint name="roller_sw_rim_back_joint" type="continuous">
    <parent link="rim_back_link"/>
    <child link="roller_sw_rim_back_link"/>
    <axis xyz="0 1 0"/>
    <origin rpy="1.0472 0 0" xyz="-0.0146 0.023 -0.0133"/>
  </joint>
  <gazebo reference="roller_sw_rim_back_link">
    <!--<mu1>5000.0</mu1>
  				<mu2>2500.0</mu2>
      			<kp  value="10000000.0" />
      			<maxContacts  value="10" />
      			<kd  value="1.0" />
      			<fdir1 value="1 0 0"/>-->
    <material>Gazebo/Grey</material>
  </gazebo>
  <!--<gazebo reference="roller_${name}_rim_${parent}_joint">
    <dampingFactor>10</dampingFactor>
    <minDepth>0.001</minDepth>
  </gazebo>-->
  <link name="roller_n_rim_back_link">
    <inertial>
      <mass value="0.1"/>
      <inertia ixx="6.8e-05" ixy="0" ixz="0" iyy="6.8e-05" iyz="0" izz="0.000101"/>
    </inertial>
    <visual>
      <geometry>
        <mesh filename="package://demo_navi/src/meshes/roller.stl"/>
      </geometry>
      <material name="roller_material">
        <color rgba="0.1 0.1 0.1 1"/>
      </material>
    </visual>
    <collision>
      <geometry>
        <mesh filename="package://demo_navi/src/meshes/roller.stl"/>
      </geometry>
    </collision>
  </link>
  <joint name="roller_n_rim_back_joint" type="continuous">
    <parent link="rim_back_link"/>
    <child link="roller_n_rim_back_link"/>
    <axis xyz="0 1 0"/>
    <origin rpy="0 0 0" xyz="-0.0146 0 0.0268"/>
  </joint>
  <gazebo reference="roller_n_rim_back_link">
    <!--<mu1>5000.0</mu1>
  				<mu2>2500.0</mu2>
      			<kp  value="10000000.0" />
      			<maxContacts  value="10" />
      			<kd  value="1.0" />
      			<fdir1 value="1 0 0"/>-->
    <material>Gazebo/Grey</material>
  </gazebo>
  <!--<gazebo reference="roller_${name}_rim_${parent}_joint">
    <dampingFactor>10</dampingFactor>
    <minDepth>0.001</minDepth>
  </gazebo>-->
  <link name="roller_se_rim_back_link">
    <inertial>
      <mass value="0.1"/>
      <inertia ixx="6.8e-05" ixy="0" ixz="0" iyy="6.8e-05" iyz="0" izz="0.000101"/>
    </inertial>
    <visual>
      <geometry>
        <mesh filename="package://demo_navi/src/meshes/roller.stl"/>
      </geometry>
      <material name="roller_material">
        <color rgba="0.1 0.1 0.1 1"/>
      </material>
    </visual>
    <collision>
      <geometry>
        <mesh filename="package://demo_navi/src/meshes/roller.stl"/>
      </geometry>
    </collision>
  </link>
  <joint name="roller_se_rim_back_joint" type="continuous">
    <parent link="rim_back_link"/>
    <child link="roller_se_rim_back_link"/>
    <axis xyz="0 1 0"/>
    <origin rpy="-1.0472 0 0" xyz="-0.0146 -0.023 -0.0133"/>
  </joint>
  <gazebo reference="roller_se_rim_back_link">
    <!--<mu1>5000.0</mu1>
  				<mu2>2500.0</mu2>
      			<kp  value="10000000.0" />
      			<maxContacts  value="10" />
      			<kd  value="1.0" />
      			<fdir1 value="1 0 0"/>-->
    <material>Gazebo/Grey</material>
  </gazebo>
  <!--<gazebo reference="roller_${name}_rim_${parent}_joint">
    <dampingFactor>10</dampingFactor>
    <minDepth>0.001</minDepth>
  </gazebo>-->
  <transmission name="rim_back_transmission">
    <type>transmission_interface/SimpleTransmission</type>
    <joint name="rim_back_joint">
      <hardwareInterface>hardware_interface/VelocityJointInterface</hardwareInterface>
    </joint>
    <actuator name="rim_back_motor">
      <hardwareInterface>hardware_interface/VelocityJointInterface</hardwareInterface>
      <mechanicalReduction>1</mechanicalReduction>
    </actuator>
  </transmission>
  <!--<gazebo reference = "rim_${name}_link">
  				<mu1>5000.0</mu1>
  				<mu2>2500.0</mu2>
      			<kp  value="10000000.0" />
      			<maxContacts  value="10" />
      			<kd  value="1.0" />
      			<fdir1 value="1 0 0"/>
		</gazebo>-->
  <!--<gazebo reference = "rim_${name}_joint">
			<dampingFactor>10</dampingFactor>
			<minDepth>0.001</minDepth>
		</gazebo>-->
  <link name="rim_right_link">
    <inertial>
      <origin xyz="0 0 0"/>
      <mass value="1"/>
      <inertia ixx="0.0007" ixy="0" ixz="0" iyy="0.0007" iyz="0" izz="0.0008"/>
    </inertial>
    <visual>
      <geometry>
        <mesh filename="package://demo_navi/src/meshes/rim.stl"/>
      </geometry>
      <material name="rim_right_material">
        <color rgba="0.3 0 0 1"/>
      </material>
    </visual>
    <collision>
      <geometry>
        <mesh filename="package://demo_navi/src/meshes/rim.stl"/>
      </geometry>
    </collision>
  </link>
  <joint name="rim_right_joint" type="continuous">
    <parent link="base_link"/>
    <child link="rim_right_link"/>
    <axis xyz="1 0 0"/>
    <origin rpy="0 0 2.0944" xyz="-0.0267 -0.214 0.04"/>
    <!--<limit effort="100000" velocity="100000"/>
			<joint_properties friction="1.0"/>-->
  </joint>
  <link name="roller_s_rim_right_link">
    <inertial>
      <mass value="0.1"/>
      <inertia ixx="6.8e-05" ixy="0" ixz="0" iyy="6.8e-05" iyz="0" izz="0.000101"/>
    </inertial>
    <visual>
      <geometry>
        <mesh filename="package://demo_navi/src/meshes/roller.stl"/>
      </geometry>
      <material name="roller_material">
        <color rgba="0.1 0.1 0.1 1"/>
      </material>
    </visual>
    <collision>
      <geometry>
        <mesh filename="package://demo_navi/src/meshes/roller.stl"/>
      </geometry>
    </collision>
  </link>
  <joint name="roller_s_rim_right_joint" type="continuous">
    <parent link="rim_right_link"/>
    <child link="roller_s_rim_right_link"/>
    <axis xyz="0 1 0"/>
    <origin rpy="0 0 0" xyz="0.0153 0 -0.0266"/>
  </joint>
  <gazebo reference="roller_s_rim_right_link">
    <!--<mu1>5000.0</mu1>
  				<mu2>2500.0</mu2>
      			<kp  value="10000000.0" />
      			<maxContacts  value="10" />
      			<kd  value="1.0" />
      			<fdir1 value="1 0 0"/>-->
    <material>Gazebo/Grey</material>
  </gazebo>
  <!--<gazebo reference="roller_${name}_rim_${parent}_joint">
    <dampingFactor>10</dampingFactor>
    <minDepth>0.001</minDepth>
  </gazebo>-->
  <link name="roller_nw_rim_right_link">
    <inertial>
      <mass value="0.1"/>
      <inertia ixx="6.8e-05" ixy="0" ixz="0" iyy="6.8e-05" iyz="0" izz="0.000101"/>
    </inertial>
    <visual>
      <geometry>
        <mesh filename="package://demo_navi/src/meshes/roller.stl"/>
      </geometry>
      <material name="roller_material">
        <color rgba="0.1 0.1 0.1 1"/>
      </material>
    </visual>
    <collision>
      <geometry>
        <mesh filename="package://demo_navi/src/meshes/roller.stl"/>
      </geometry>
    </collision>
  </link>
  <joint name="roller_nw_rim_right_joint" type="continuous">
    <parent link="rim_right_link"/>
    <child link="roller_nw_rim_right_link"/>
    <axis xyz="0 1 0"/>
    <origin rpy="1.0472 0 0" xyz="0.015 -0.0231 0.0131"/>
  </joint>
  <gazebo reference="roller_nw_rim_right_link">
    <!--<mu1>5000.0</mu1>
  				<mu2>2500.0</mu2>
      			<kp  value="10000000.0" />
      			<maxContacts  value="10" />
      			<kd  value="1.0" />
      			<fdir1 value="1 0 0"/>-->
    <material>Gazebo/Grey</material>
  </gazebo>
  <!--<gazebo reference="roller_${name}_rim_${parent}_joint">
    <dampingFactor>10</dampingFactor>
    <minDepth>0.001</minDepth>
  </gazebo>-->
  <link name="roller_ne_rim_right_link">
    <inertial>
      <mass value="0.1"/>
      <inertia ixx="6.8e-05" ixy="0" ixz="0" iyy="6.8e-05" iyz="0" izz="0.000101"/>
    </inertial>
    <visual>
      <geometry>
        <mesh filename="package://demo_navi/src/meshes/roller.stl"/>
      </geometry>
      <material name="roller_material">
        <color rgba="0.1 0.1 0.1 1"/>
      </material>
    </visual>
    <collision>
      <geometry>
        <mesh filename="package://demo_navi/src/meshes/roller.stl"/>
      </geometry>
    </collision>
  </link>
  <joint name="roller_ne_rim_right_joint" type="continuous">
    <parent link="rim_right_link"/>
    <child link="roller_ne_rim_right_link"/>
    <axis xyz="0 1 0"/>
    <origin rpy="-1.0472 0 0" xyz="0.015 0.0231 0.0135"/>
  </joint>
  <gazebo reference="roller_ne_rim_right_link">
    <!--<mu1>5000.0</mu1>
  				<mu2>2500.0</mu2>
      			<kp  value="10000000.0" />
      			<maxContacts  value="10" />
      			<kd  value="1.0" />
      			<fdir1 value="1 0 0"/>-->
    <material>Gazebo/Grey</material>
  </gazebo>
  <!--<gazebo reference="roller_${name}_rim_${parent}_joint">
    <dampingFactor>10</dampingFactor>
    <minDepth>0.001</minDepth>
  </gazebo>-->
  <link name="roller_sw_rim_right_link">
    <inertial>
      <mass value="0.1"/>
      <inertia ixx="6.8e-05" ixy="0" ixz="0" iyy="6.8e-05" iyz="0" izz="0.000101"/>
    </inertial>
    <visual>
      <geometry>
        <mesh filename="package://demo_navi/src/meshes/roller.stl"/>
      </geometry>
      <material name="roller_material">
        <color rgba="0.1 0.1 0.1 1"/>
      </material>
    </visual>
    <collision>
      <geometry>
        <mesh filename="package://demo_navi/src/meshes/roller.stl"/>
      </geometry>
    </collision>
  </link>
  <joint name="roller_sw_rim_right_joint" type="continuous">
    <parent link="rim_right_link"/>
    <child link="roller_sw_rim_right_link"/>
    <axis xyz="0 1 0"/>
    <origin rpy="1.0472 0 0" xyz="-0.0146 0.023 -0.0133"/>
  </joint>
  <gazebo reference="roller_sw_rim_right_link">
    <!--<mu1>5000.0</mu1>
  				<mu2>2500.0</mu2>
      			<kp  value="10000000.0" />
      			<maxContacts  value="10" />
      			<kd  value="1.0" />
      			<fdir1 value="1 0 0"/>-->
    <material>Gazebo/Grey</material>
  </gazebo>
  <!--<gazebo reference="roller_${name}_rim_${parent}_joint">
    <dampingFactor>10</dampingFactor>
    <minDepth>0.001</minDepth>
  </gazebo>-->
  <link name="roller_n_rim_right_link">
    <inertial>
      <mass value="0.1"/>
      <inertia ixx="6.8e-05" ixy="0" ixz="0" iyy="6.8e-05" iyz="0" izz="0.000101"/>
    </inertial>
    <visual>
      <geometry>
        <mesh filename="package://demo_navi/src/meshes/roller.stl"/>
      </geometry>
      <material name="roller_material">
        <color rgba="0.1 0.1 0.1 1"/>
      </material>
    </visual>
    <collision>
      <geometry>
        <mesh filename="package://demo_navi/src/meshes/roller.stl"/>
      </geometry>
    </collision>
  </link>
  <joint name="roller_n_rim_right_joint" type="continuous">
    <parent link="rim_right_link"/>
    <child link="roller_n_rim_right_link"/>
    <axis xyz="0 1 0"/>
    <origin rpy="0 0 0" xyz="-0.0146 0 0.0268"/>
  </joint>
  <gazebo reference="roller_n_rim_right_link">
    <!--<mu1>5000.0</mu1>
  				<mu2>2500.0</mu2>
      			<kp  value="10000000.0" />
      			<maxContacts  value="10" />
      			<kd  value="1.0" />
      			<fdir1 value="1 0 0"/>-->
    <material>Gazebo/Grey</material>
  </gazebo>
  <!--<gazebo reference="roller_${name}_rim_${parent}_joint">
    <dampingFactor>10</dampingFactor>
    <minDepth>0.001</minDepth>
  </gazebo>-->
  <link name="roller_se_rim_right_link">
    <inertial>
      <mass value="0.1"/>
      <inertia ixx="6.8e-05" ixy="0" ixz="0" iyy="6.8e-05" iyz="0" izz="0.000101"/>
    </inertial>
    <visual>
      <geometry>
        <mesh filename="package://demo_navi/src/meshes/roller.stl"/>
      </geometry>
      <material name="roller_material">
        <color rgba="0.1 0.1 0.1 1"/>
      </material>
    </visual>
    <collision>
      <geometry>
        <mesh filename="package://demo_navi/src/meshes/roller.stl"/>
      </geometry>
    </collision>
  </link>
  <joint name="roller_se_rim_right_joint" type="continuous">
    <parent link="rim_right_link"/>
    <child link="roller_se_rim_right_link"/>
    <axis xyz="0 1 0"/>
    <origin rpy="-1.0472 0 0" xyz="-0.0146 -0.023 -0.0133"/>
  </joint>
  <gazebo reference="roller_se_rim_right_link">
    <!--<mu1>5000.0</mu1>
  				<mu2>2500.0</mu2>
      			<kp  value="10000000.0" />
      			<maxContacts  value="10" />
      			<kd  value="1.0" />
      			<fdir1 value="1 0 0"/>-->
    <material>Gazebo/Grey</material>
  </gazebo>
  <!--<gazebo reference="roller_${name}_rim_${parent}_joint">
    <dampingFactor>10</dampingFactor>
    <minDepth>0.001</minDepth>
  </gazebo>-->
  <transmission name="rim_right_transmission">
    <type>transmission_interface/SimpleTransmission</type>
    <joint name="rim_right_joint">
      <hardwareInterface>hardware_interface/VelocityJointInterface</hardwareInterface>
    </joint>
    <actuator name="rim_right_motor">
      <hardwareInterface>hardware_interface/VelocityJointInterface</hardwareInterface>
      <mechanicalReduction>1</mechanicalReduction>
    </actuator>
  </transmission>
  <!--<gazebo reference = "rim_${name}_link">
  				<mu1>5000.0</mu1>
  				<mu2>2500.0</mu2>
      			<kp  value="10000000.0" />
      			<maxContacts  value="10" />
      			<kd  value="1.0" />
      			<fdir1 value="1 0 0"/>
		</gazebo>-->
  <!--<gazebo reference = "rim_${name}_joint">
			<dampingFactor>10</dampingFactor>
			<minDepth>0.001</minDepth>
		</gazebo>-->
  <joint name="sick_joint_R" type="fixed">
    <parent link="base_link"/>
    <child link="sick_R_laser"/>
    <!-- allakse to adress -->
    <origin rpy="-3.1415 0 -1.0472" xyz="0.008 -0.275 0.042"/>
  </joint>
  <link name="sick_R_laser">
    <visual>
      <geometry>
        <mesh filename="package://demo_navi/src/meshes/sick_tim_5xx.stl"/>
      </geometry>
      <material name="blue">
        <color rgba="0 0 1 1"/>
      </material>
    </visual>
    <collision>
      <geometry>
        <mesh filename="package://demo_navi/src/meshes/sick_tim_5xx.stl"/>
      </geometry>
    </collision>
    <inertial>
      <mass value="0.001"/>
      <origin xyz="0.008 -0.275 0.042"/>
      <inertia ixx="0.000001" ixy="0.0" ixz="0.0" iyy="0.000001" iyz="0.0" izz="0.000001"/>
    </inertial>
  </link>
  <joint name="sick_joint_L" type="fixed">
    <parent link="base_link"/>
    <child link="sick_L_laser"/>
    <origin rpy="-3.1415 0 1.0472" xyz="0.008 0.275 0.042"/>
  </joint>
  <link name="sick_L_laser">
    <visual>
      <geometry>
        <mesh filename="package://demo_navi/src/meshes/sick_tim_5xx.stl"/>
      </geometry>
      <material name="blue">
        <color rgba="0 0 1 1"/>
      </material>
    </visual>
    <collision>
      <geometry>
        <mesh filename="package://demo_navi/src/meshes/sick_tim_5xx.stl"/>
      </geometry>
    </collision>
    <inertial>
      <mass value="0.001"/>
      <origin xyz="0 0.27 0.07"/>
      <inertia ixx="0.000001" ixy="0.0" ixz="0.0" iyy="0.000001" iyz="0.0" izz="0.000001"/>
    </inertial>
  </link>
  <!--WIDOWXL ARM LINKS & JOINTS-->
  <link name="shoulder_link">
    <visual>
      <origin rpy="0 0 0" xyz="0 0 0"/>
      <geometry>
        <mesh filename="package://demo_navi/src/meshes/arm/shoulder_link.stl"/>
      </geometry>
      <material name="">
        <color rgba="0.15 0.15 0.15 1.0"/>
      </material>
    </visual>
    <collision>
      <origin rpy="0 0 0" xyz="0 0 0"/>
      <geometry>
        <mesh filename="package://demo_navi/src/meshes/arm/shoulder_link.stl"/>
      </geometry>
    </collision>
    <inertial>
      <origin rpy="0 0 0" xyz="0 0 0"/>
      <mass value="0.01"/>
      <inertia ixx="0.01" ixy="0.0" ixz="0.0" iyy="0.01" iyz="0.0" izz="0.01"/>
    </inertial>
  </link>
  <link name="biceps_link">
    <visual>
      <origin rpy="0 0 0" xyz="0.04825 0 0.14"/>
      <geometry>
        <mesh filename="package://demo_navi/src/meshes/arm/biceps_link.stl"/>
      </geometry>
      <material name="">
        <color rgba="0.15 0.15 0.15 1.0"/>
      </material>
    </visual>
    <collision>
      <origin rpy="0 0 0" xyz="0.04825 0 0.14"/>
      <geometry>
        <mesh filename="package://demo_navi/src/meshes/arm/biceps_link.stl"/>
      </geometry>
    </collision>
    <inertial>
      <origin rpy="0 0 0" xyz="0.04825 0 0.14"/>
      <mass value="0.01"/>
      <inertia ixx="0.01" ixy="0.0" ixz="0.0" iyy="0.01" iyz="0.0" izz="0.01"/>
    </inertial>
  </link>
  <link name="forearm_link">
    <visual>
      <origin rpy="0 0 0" xyz="0 0 0.14203"/>
      <geometry>
        <mesh filename="package://demo_navi/src/meshes/arm/forearm_link.stl"/>
      </geometry>
      <material name="">
        <color rgba="0.15 0.15 0.15 1.0"/>
      </material>
    </visual>
    <collision>
      <origin rpy="0 0 0" xyz="0 0 0.14203"/>
      <geometry>
        <mesh filename="package://demo_navi/src/meshes/arm/forearm_link.stl"/>
      </geometry>
    </collision>
    <inertial>
      <origin rpy="0 0 0" xyz="0 0 0.14203"/>
      <mass value="0.01"/>
      <inertia ixx="0.01" ixy="0.0" ixz="0.0" iyy="0.01" iyz="0.0" izz="0.01"/>
    </inertial>
  </link>
  <link name="wrist_1_link">
    <visual>
      <origin rpy="0 0 0" xyz="0 0 0"/>
      <geometry>
        <mesh filename="package://demo_navi/src/meshes/arm/wrist_1_link.stl"/>
      </geometry>
      <material name="">
        <color rgba="0.15 0.15 0.15 1.0"/>
      </material>
    </visual>
    <collision>
      <origin rpy="0 0 0" xyz="0 0 0"/>
      <geometry>
        <mesh filename="package://demo_navi/src/meshes/arm/wrist_1_link.stl"/>
      </geometry>
    </collision>
    <inertial>
      <origin rpy="0 0 0" xyz="0 0 0"/>
      <mass value="0.01"/>
      <inertia ixx="0.01" ixy="0.0" ixz="0.0" iyy="0.01" iyz="0.0" izz="0.01"/>
    </inertial>
  </link>
  <link name="wrist_2_link">
    <visual>
      <origin rpy="0 0 0" xyz="0 0 0.043"/>
      <geometry>
        <mesh filename="package://demo_navi/src/meshes/arm/wrist_2_link.stl"/>
      </geometry>
      <material name="">
        <color rgba="0.15 0.15 0.15 1.0"/>
      </material>
    </visual>
    <collision>
      <origin rpy="0 0 0" xyz="0 0 0.043"/>
      <geometry>
        <mesh filename="package://demo_navi/src/meshes/arm/wrist_2_link.stl"/>
      </geometry>
    </collision>
    <inertial>
      <origin rpy="0 0 0" xyz="0 0 0.043"/>
      <mass value="0.01"/>
      <inertia ixx="0.01" ixy="0.0" ixz="0.0" iyy="0.01" iyz="0.0" izz="0.01"/>
    </inertial>
  </link>
  <link name="gripper_rail_link">
    <visual>
      <origin rpy="0 0 1.57" xyz="0 0 0"/>
      <geometry>
        <mesh filename="package://demo_navi/src/meshes/arm/gripper_rail_link.stl"/>
      </geometry>
      <material name="">
        <color rgba="0.15 0.15 0.15 1.0"/>
      </material>
    </visual>
    <collision>
      <origin rpy="0 0 1.57" xyz="0 0 0"/>
      <geometry>
        <mesh filename="package://demo_navi/src/meshes/arm/gripper_rail_link.stl"/>
      </geometry>
    </collision>
    <inertial>
      <origin rpy="0 0 1.57" xyz="0 0 0"/>
      <mass value="0.01"/>
      <inertia ixx="0.01" ixy="0.0" ixz="0.0" iyy="0.01" iyz="0.0" izz="0.01"/>
    </inertial>
  </link>
  <link name="gripper_aux_link">
      </link>
  <link name="gripper_1_link">
    <visual>
      <origin rpy="0 0 1.57" xyz="0 -0.0007 0"/>
      <geometry>
        <mesh filename="package://demo_navi/src/meshes/arm/gripper_hand_fixed_link.stl"/>
      </geometry>
      <material name="">
        <color rgba="0.15 0.15 0.15 1.0"/>
      </material>
    </visual>
    <collision>
      <origin rpy="0 0 1.57" xyz="0 -0.0007 0"/>
      <geometry>
        <mesh filename="package://demo_navi/src/meshes/arm/gripper_hand_fixed_link.stl"/>
      </geometry>
    </collision>
    <inertial>
      <origin rpy="0 0 1.57" xyz="0 -0.0007 0"/>
      <mass value="0.01"/>
      <inertia ixx="0.01" ixy="0.0" ixz="0.0" iyy="0.01" iyz="0.0" izz="0.01"/>
    </inertial>
  </link>
  <link name="gripper_2_link">
    <visual>
      <origin rpy="0 0 -1.57" xyz="0 0.0007 0"/>
      <geometry>
        <mesh filename="package://demo_navi/src/meshes/arm/gripper_hand_fixed_link.stl"/>
      </geometry>
      <material name="">
        <color rgba="0.15 0.15 0.15 1.0"/>
      </material>
    </visual>
    <collision>
      <origin rpy="0 0 -1.57" xyz="0 0.0007 0"/>
      <geometry>
        <mesh filename="package://demo_navi/src/meshes/arm/gripper_hand_fixed_link.stl"/>
      </geometry>
    </collision>
    <inertial>
      <origin rpy="0 0 -1.57" xyz="0 0.0007 0"/>
      <mass value="0.01"/>
      <inertia ixx="0.01" ixy="0.0" ixz="0.0" iyy="0.01" iyz="0.0" izz="0.01"/>
    </inertial>
  </link>
  <!-- joints -->
  <joint name="joint_1" type="revolute">
    <origin rpy="0 0 0" xyz="0 0 0.15"/>
    <parent link="base_link"/>
    <child link="shoulder_link"/>
    <axis xyz="0 0 1"/>
    <limit effort="100" lower="-3.1415" upper="3.1415" velocity="0.785"/>
  </joint>
  <joint name="joint_2" type="revolute">
    <!--origin xyz="0.04825 0 0.14203" rpy="0 0 0" /-->
    <origin rpy="0 0 0" xyz="0 0 0"/>
    <parent link="shoulder_link"/>
    <child link="biceps_link"/>
    <axis xyz="0 1 0"/>
    <limit effort="100" lower="-1.571" upper="1.571" velocity="1.571"/>
  </joint>
  <joint name="joint_3" type="revolute">
    <origin rpy="0 1.571 0" xyz="0.04825 0 0.14203"/>
    <parent link="biceps_link"/>
    <child link="forearm_link"/>
    <axis xyz="0 1 0"/>
    <limit effort="100" lower="-1.571" upper="1.571" velocity="1.571"/>
  </joint>
  <joint name="joint_4" type="revolute">
    <origin rpy="0 0 0" xyz="0 0 0.14203"/>
    <parent link="forearm_link"/>
    <child link="wrist_1_link"/>
    <axis xyz="0 1 0"/>
    <limit effort="100" lower="-1.745" upper="1.745" velocity="1.571"/>
  </joint>
  <joint name="joint_5" type="revolute">
    <origin rpy="0 0 0" xyz="0 0 0.0715"/>
    <parent link="wrist_1_link"/>
    <child link="wrist_2_link"/>
    <axis xyz="0 0 1"/>
    <limit effort="100" lower="-2.617" upper="2.617" velocity="1.571"/>
  </joint>
  <joint name="joint_6" type="fixed">
    <origin rpy="0 0 0" xyz="0 0 0.043"/>
    <parent link="wrist_2_link"/>
    <child link="gripper_rail_link"/>
    <axis xyz="0 0 1"/>
    <limit effort="100" lower="-0.31" upper="0.1" velocity="0.5"/>
  </joint>
  <joint name="gripper_revolute_joint" type="revolute">
    <origin rpy="0 0 0" xyz="0 0 0"/>
    <parent link="gripper_rail_link"/>
    <child link="gripper_aux_link"/>
    <axis xyz="0 0 1"/>
    <limit effort="100" lower="0" upper="2.6" velocity="0.5"/>
  </joint>
  <joint name="gripper_prismatic_joint_1" type="prismatic">
    <origin rpy="0 0 0" xyz="0 0 0"/>
    <parent link="gripper_rail_link"/>
    <child link="gripper_1_link"/>
    <axis xyz="0 -1 0"/>
    <limit effort="100" lower="0" upper="0.027" velocity="0.5"/>
  </joint>
  <joint name="gripper_prismatic_joint_2" type="prismatic">
    <origin rpy="0 0 0" xyz="0 0 0"/>
    <parent link="gripper_rail_link"/>
    <child link="gripper_2_link"/>
    <mimic joint="gripper_prismatic_joint_1"/>
    <axis xyz="0 1 0"/>
    <limit effort="100" lower="0" upper="0.027" velocity="0.5"/>
  </joint>
  <transmission name="tran1">
    <type>transmission_interface/SimpleTransmission</type>
    <joint name="joint_1">
      <hardwareInterface>hardware_interface/PositionJointInterface</hardwareInterface>
    </joint>
    <actuator name="motor1">
      <hardwareInterface>hardware_interface/PositionJointInterface</hardwareInterface>
      <mechanicalReduction>1</mechanicalReduction>
    </actuator>
  </transmission>
  <transmission name="tran2">
    <type>transmission_interface/SimpleTransmission</type>
    <joint name="joint_2">
      <hardwareInterface>hardware_interface/PositionJointInterface</hardwareInterface>
    </joint>
    <actuator name="motor2">
      <hardwareInterface>hardware_interface/PositionJointInterface</hardwareInterface>
      <mechanicalReduction>1</mechanicalReduction>
    </actuator>
  </transmission>
  <transmission name="tran3">
    <type>transmission_interface/SimpleTransmission</type>
    <joint name="joint_3">
      <hardwareInterface>hardware_interface/PositionJointInterface</hardwareInterface>
    </joint>
    <actuator name="motor3">
      <hardwareInterface>hardware_interface/PositionJointInterface</hardwareInterface>
      <mechanicalReduction>1</mechanicalReduction>
    </actuator>
  </transmission>
  <transmission name="tran4">
    <type>transmission_interface/SimpleTransmission</type>
    <joint name="joint_4">
      <hardwareInterface>hardware_interface/PositionJointInterface</hardwareInterface>
    </joint>
    <actuator name="motor4">
      <hardwareInterface>hardware_interface/PositionJointInterface</hardwareInterface>
      <mechanicalReduction>1</mechanicalReduction>
    </actuator>
  </transmission>
  <transmission name="tran5">
    <type>transmission_interface/SimpleTransmission</type>
    <joint name="joint_5">
      <hardwareInterface>hardware_interface/PositionJointInterface</hardwareInterface>
    </joint>
    <actuator name="motor5">
      <hardwareInterface>hardware_interface/PositionJointInterface</hardwareInterface>
      <mechanicalReduction>1</mechanicalReduction>
    </actuator>
  </transmission>
  <transmission name="tran7">
    <type>transmission_interface/SimpleTransmission</type>
    <joint name="gripper_prismatic_joint_1">
      <hardwareInterface>hardware_interface/PositionJointInterface</hardwareInterface>
    </joint>
    <actuator name="motor7">
      <hardwareInterface>hardware_interface/PositionJointInterface</hardwareInterface>
      <mechanicalReduction>1</mechanicalReduction>
    </actuator>
  </transmission>
  <transmission name="tran8">
    <type>transmission_interface/SimpleTransmission</type>
    <joint name="gripper_prismatic_joint_2">
      <hardwareInterface>hardware_interface/PositionJointInterface</hardwareInterface>
    </joint>
    <actuator name="motor8">
      <hardwareInterface>hardware_interface/PositionJointInterface</hardwareInterface>
      <mechanicalReduction>1</mechanicalReduction>
    </actuator>
  </transmission>
  <gazebo>
    <plugin filename="libgazebo_ros_control.so" name="gazebo_ros_control">
      <robotNamespace>/demo_DIR</robotNamespace>
    </plugin>
  </gazebo>
  <!--<gazebo reference="base_link">
	<dampingFactor>10</dampingFactor>
	<minDepth>0.001</minDepth>
   </gazebo>-->
  <gazebo>
    <plugin filename="libgazebo_ros_planar_move.so" name="object_controller">
      <commandTopic>/gaz_controller/cmd_vel</commandTopic>
      <leftJoint>left_rim_joint</leftJoint>
      <rightJoint>right_rim_joint</rightJoint>
      <backJoint>back_rim_joint</backJoint>
      <wheelSeparation>0.25</wheelSeparation>
      <wheelDiameter>0.7</wheelDiameter>
      <torque>10</torque>
      <odometryTopic>odom</odometryTopic>
      <odometryFrame>odom</odometryFrame>
      <odometryRate>20.0</odometryRate>
      <robotBaseFrame>base_footprint</robotBaseFrame>
    </plugin>
  </gazebo>
  <gazebo reference="sick_L_laser">
    <material value="Gazebo/Blue"/>
    <sensor name="sick_lms_5_laser_gazebo_v0" type="ray">
      <always_on>true</always_on>
      <update_rate>15.0</update_rate>
      <pose>0 0 0 0 0 0</pose>
      <visualize>false</visualize>
      <ray>
        <scan>
          <horizontal>
            <samples>811</samples>
            <resolution>1</resolution>
            <min_angle>-1.0</min_angle>
            <!--90 moires -->
            <max_angle>2.357</max_angle>
            <!--140 moires -->
          </horizontal>
        </scan>
        <range>
          <min>0.15</min>
          <max>4.0</max>
          <resolution>0.01</resolution>
        </range>
      </ray>
      <plugin filename="libgazebo_ros_laser.so" name="gazebo_ros_sick_lms_5_laser_gazebo_v0_controller">
        <gaussianNoise>0.005</gaussianNoise>
        <alwaysOn>true</alwaysOn>
        <updateRate>15.0</updateRate>
        <topicName>scan_L</topicName>
        <frameName>sick_L_laser</frameName>
      </plugin>
    </sensor>
  </gazebo>
  <gazebo reference="sick_R_laser">
    <material value="Gazebo/Blue"/>
    <sensor name="sick_lms_5_laser_gazebo_v01" type="ray">
      <always_on>true</always_on>
      <update_rate>15.0</update_rate>
      <pose>0 0 0 0 0 0</pose>
      <visualize>false</visualize>
      <ray>
        <scan>
          <horizontal>
            <samples>811</samples>
            <resolution>1</resolution>
            <min_angle>-2.357</min_angle>
            <!--140 moires -->
            <max_angle>1.0</max_angle>
            <!--90 moires -->
          </horizontal>
        </scan>
        <range>
          <min>0.15</min>
          <max>4.0</max>
          <resolution>0.01</resolution>
        </range>
      </ray>
      <plugin filename="libgazebo_ros_laser.so" name="gazebo_ros_sick_lms_5_laser_gazebo_v01_controller">
        <gaussianNoise>0.005</gaussianNoise>
        <alwaysOn>true</alwaysOn>
        <updateRate>15.0</updateRate>
        <topicName>scan_R</topicName>
        <frameName>sick_R_laser</frameName>
      </plugin>
    </sensor>
  </gazebo>
  <gazebo reference="base_link">
    <material>Gazebo/Crimson</material>
  </gazebo>
  <gazebo reference="rim_left_link">
    <material>Gazebo/Black</material>
  </gazebo>
  <gazebo reference="rim_back_link">
    <material>Gazebo/Black</material>
  </gazebo>
  <gazebo reference="rim_right_link">
    <material>Gazebo/Black</material>
  </gazebo>
</robot>
