<?xml version="1.0" ?>
<robot xmlns:xacro="http://www.ros.org/wiki/xacro">

	<xacro:macro
		name="roller_macro"
		params="parent name xyz rpy"
	>

		<link name="roller_${name}_rim_${parent}_link">

			<inertial>

				<mass value="0.1"/>
				<inertia
					ixx="6.008e-07"
					ixy="0"
					ixz="0"
					iyy="6.008e-07"
					iyz="0"
					izz="0.0000000101"
				/>

			</inertial>
			<visual>

				<geometry>

					<mesh filename="package://demo_navi/src/meshes/roller.stl"/>

				</geometry>
				<material name="roller_material">

					<color rgba="0.1 0.1 0.1 1"/>

				</material>

			</visual>
			<collision>

				<geometry>

					<mesh filename="package://demo_navi/src/meshes/roller.stl"/>

				</geometry>
			</collision>

		</link>
		<joint
			name="roller_${name}_rim_${parent}_joint"
			type="continuous"
		>

			<parent link="rim_${parent}_link"/>
			<child link="roller_${name}_rim_${parent}_link"/>
			<axis xyz="0 1 0"/>
			<origin
				xyz="${xyz}"
				rpy="${rpy}"
			/>
			<limit effort="100000000" velocity="1000000000"/>
			<joint_properties friction="1.0"/>
		</joint>
	<gazebo reference="roller_${name}_rim_${parent}_link">
  			<mu1>50.0</mu1>
  			<mu2>25.0</mu2>
      		<kp  value="10000000000.0" />
      		<kd  value="10000000000.0" />
    	  	<dampingFactor>10</dampingFactor>
    		<minDepth>0.001</minDepth>

    <material>Gazebo/Grey</material>
  </gazebo>
  <selfCollide>False</selfCollide>
  <!--<gazebo reference="roller_${name}_rim_${parent}_joint">
    <dampingFactor>10</dampingFactor>
    <minDepth>0.001</minDepth>
  </gazebo>-->
	</xacro:macro>

</robot>
