<?xml version="1.0" ?>
<robot 
   xmlns:xacro="http://www.ros.org/wiki/xacro">

	<xacro:include filename="$(find demo_navi)/src/urdf/xacro/fffroller.urdf.xacro"/>

	<xacro:macro
		name="rim_macro"
		params="name color xyz rpy"
	>

		<link name="rim_${name}_link">

			<inertial>

				<origin xyz="0 0 0"/>
				<mass value="0.8"/>
				<inertia
					ixx="1.112e-08"
					ixy="0"
					ixz="0"
					iyy="1.112e-08"
					iyz="0"
					izz="1.1832e-08"
				/>
			</inertial>
			<visual>

				<geometry>

					<mesh filename="package://demo_navi/src/meshes/frim.stl"/>

				</geometry>
				<material name="rim_${name}_material">

					<color rgba="${color} 1"/>

				</material>

			</visual>
			<collision>

				<geometry>

					<mesh filename="package://demo_navi/src/meshes/frim.stl"/>

				</geometry>

			</collision>

		</link>
		<joint
			name="rim_${name}_joint"
			type="continuous"
		>

			<parent link="base_link" />
			<child link="rim_${name}_link" />
			<axis xyz="0 0 1"/>
			<origin
				xyz="${xyz}"
				rpy="${rpy}"
			/>
		</joint>
		<xacro:roller_macro
			parent="${name}"
			name="w"
			xyz="-0.0243 0 0.0138"
			rpy="-1.5708 0 0"
		/>
		<xacro:roller_macro
			parent="${name}"
			name="ne"
			xyz="0.01218 0.02095 0.0138"
			rpy="-1.5708 0 -2.0944"
		/>
		<xacro:roller_macro
			parent="${name}"
			name="se"
			xyz="0.01218 -0.02095 0.0138"
			rpy="-1.5708 0 -1.0472"
		/>
		<xacro:roller_macro
			parent="${name}"
			name="e"
			xyz="0.0243 0 -0.0135"
			rpy="-1.5708 0 0"
		/>
		<xacro:roller_macro
			parent="${name}"
			name="sw"
			xyz="-0.01218 0.02095 -0.0135"
			rpy="0 0 3.1415"
		/>
		<xacro:roller_macro
			parent="${name}"
			name="nw"
			xyz="-0.01218 -0.02095 -0.0135"
			rpy="-1.5708 0 -2.0944"
		/>
		<transmission name="rim_${name}_transmission">

			<type>transmission_interface/SimpleTransmission</type>
			<joint name="rim_${name}_joint">

				<hardwareInterface>hardware_interface/VelocityJointInterface</hardwareInterface>

			</joint>
			<actuator name="rim_${name}_motor">

				<hardwareInterface>hardware_interface/VelocityJointInterface</hardwareInterface>
				<mechanicalReduction>1</mechanicalReduction>

			</actuator>

		</transmission>


	</xacro:macro>

</robot>
